package de.MiningPickaxe.structures;

import java.util.Random;

import net.minecraft.block.Block;
import net.minecraft.block.material.Material;
import net.minecraft.init.Blocks;
import net.minecraft.world.World;
import net.minecraft.world.gen.feature.WorldGenerator;

public class StructureDungeon1 extends WorldGenerator
{
	protected Block[] GetValidSpawnBlocks()
	{
		return new Block[]
		{
			Blocks.sand,
		};
	}

	public boolean LocationIsValidSpawn(World world, int x, int y, int z)
 {

		Block checkBlock = world.getBlock(x, y - 1, z);
		Block blockAbove = world.getBlock(x, y , z);
		Block blockBelow = world.getBlock(x, y - 2, z);

		for (Block i : GetValidSpawnBlocks())
		{
			if (blockAbove != Blocks.air)
			{
				return false;
			}
			if (checkBlock == i)
			{
				return true;
			}
			else if (checkBlock == Blocks.snow_layer && blockBelow == i)
			{
				return true;
			}
			else if (checkBlock.getMaterial() == Material.plants && blockBelow == i)
			{
				return true;
			}
		}
		return false;
	}

	public boolean generate(World world, Random rand, int x, int y, int z)
	{
		int i = rand.nextInt(1);

		if(i == 0)
		{
		    generate_r0(world, rand, x, y, z);
		}

       return true;

	}

	public boolean generate_r0(World world, Random rand, int x, int y, int z)
	{
		if(!LocationIsValidSpawn(world, x, y, z) || !LocationIsValidSpawn(world, x + 29, y, z) || !LocationIsValidSpawn(world, x + 29, y, z + 61) || !LocationIsValidSpawn(world, x, y, z + 61))
		{
			return false;
		}

		world.setBlock(x + 0, y + -10, z + 3, Blocks.bedrock, 0, 3);
		world.setBlock(x + 1, y + -10, z + 3, Blocks.bedrock, 0, 3);
		world.setBlock(x + 2, y + -10, z + 3, Blocks.bedrock, 0, 3);
		world.setBlock(x + 3, y + -10, z + 3, Blocks.bedrock, 0, 3);
		world.setBlock(x + 4, y + -10, z + 3, Blocks.bedrock, 0, 3);
		world.setBlock(x + 5, y + -10, z + 3, Blocks.bedrock, 0, 3);
		world.setBlock(x + 6, y + -10, z + 3, Blocks.bedrock, 0, 3);
		world.setBlock(x + 7, y + -10, z + 3, Blocks.bedrock, 0, 3);
		world.setBlock(x + 8, y + -10, z + 3, Blocks.bedrock, 0, 3);
		world.setBlock(x + 9, y + -10, z + 3, Blocks.bedrock, 0, 3);
		world.setBlock(x + 10, y + -10, z + 3, Blocks.bedrock, 0, 3);
		world.setBlock(x + 11, y + -10, z + 3, Blocks.bedrock, 0, 3);
		world.setBlock(x + 12, y + -10, z + 3, Blocks.bedrock, 0, 3);
		world.setBlock(x + 13, y + -10, z + 3, Blocks.bedrock, 0, 3);
		world.setBlock(x + 14, y + -10, z + 3, Blocks.bedrock, 0, 3);
		world.setBlock(x + 15, y + -10, z + 3, Blocks.bedrock, 0, 3);
		world.setBlock(x + 16, y + -10, z + 3, Blocks.bedrock, 0, 3);
		world.setBlock(x + 17, y + -10, z + 3, Blocks.bedrock, 0, 3);
		world.setBlock(x + 18, y + -10, z + 3, Blocks.bedrock, 0, 3);
		world.setBlock(x + 19, y + -10, z + 3, Blocks.bedrock, 0, 3);
		world.setBlock(x + 20, y + -10, z + 3, Blocks.bedrock, 0, 3);
		world.setBlock(x + 21, y + -10, z + 3, Blocks.bedrock, 0, 3);
		world.setBlock(x + 22, y + -10, z + 3, Blocks.bedrock, 0, 3);
		world.setBlock(x + 23, y + -10, z + 3, Blocks.bedrock, 0, 3);
		world.setBlock(x + 24, y + -10, z + 3, Blocks.bedrock, 0, 3);
		world.setBlock(x + 25, y + -10, z + 3, Blocks.bedrock, 0, 3);
		world.setBlock(x + 26, y + -10, z + 3, Blocks.bedrock, 0, 3);
		world.setBlock(x + 27, y + -10, z + 3, Blocks.bedrock, 0, 3);
		world.setBlock(x + 28, y + -10, z + 3, Blocks.bedrock, 0, 3);
		world.setBlock(x + 0, y + -10, z + 4, Blocks.bedrock, 0, 3);
		world.setBlock(x + 1, y + -10, z + 4, Blocks.stone, 0, 3);
		world.setBlock(x + 2, y + -10, z + 4, Blocks.stone, 0, 3);
		world.setBlock(x + 3, y + -10, z + 4, Blocks.stone, 0, 3);
		world.setBlock(x + 4, y + -10, z + 4, Blocks.stone, 0, 3);
		world.setBlock(x + 5, y + -10, z + 4, Blocks.stone, 0, 3);
		world.setBlock(x + 6, y + -10, z + 4, Blocks.stone, 0, 3);
		world.setBlock(x + 7, y + -10, z + 4, Blocks.stone, 0, 3);
		world.setBlock(x + 8, y + -10, z + 4, Blocks.stone, 0, 3);
		world.setBlock(x + 9, y + -10, z + 4, Blocks.stone, 0, 3);
		world.setBlock(x + 10, y + -10, z + 4, Blocks.planks, 0, 3);
		world.setBlock(x + 11, y + -10, z + 4, Blocks.planks, 0, 3);
		world.setBlock(x + 12, y + -10, z + 4, Blocks.planks, 0, 3);
		world.setBlock(x + 13, y + -10, z + 4, Blocks.planks, 0, 3);
		world.setBlock(x + 14, y + -10, z + 4, Blocks.planks, 0, 3);
		world.setBlock(x + 15, y + -10, z + 4, Blocks.planks, 0, 3);
		world.setBlock(x + 16, y + -10, z + 4, Blocks.planks, 0, 3);
		world.setBlock(x + 17, y + -10, z + 4, Blocks.planks, 0, 3);
		world.setBlock(x + 18, y + -10, z + 4, Blocks.planks, 0, 3);
		world.setBlock(x + 19, y + -10, z + 4, Blocks.planks, 0, 3);
		world.setBlock(x + 20, y + -10, z + 4, Blocks.planks, 0, 3);
		world.setBlock(x + 21, y + -10, z + 4, Blocks.planks, 0, 3);
		world.setBlock(x + 22, y + -10, z + 4, Blocks.planks, 0, 3);
		world.setBlock(x + 23, y + -10, z + 4, Blocks.planks, 0, 3);
		world.setBlock(x + 24, y + -10, z + 4, Blocks.planks, 0, 3);
		world.setBlock(x + 25, y + -10, z + 4, Blocks.planks, 0, 3);
		world.setBlock(x + 26, y + -10, z + 4, Blocks.planks, 0, 3);
		world.setBlock(x + 27, y + -10, z + 4, Blocks.planks, 0, 3);
		world.setBlock(x + 28, y + -10, z + 4, Blocks.bedrock, 0, 3);
		world.setBlock(x + 0, y + -10, z + 5, Blocks.bedrock, 0, 3);
		world.setBlock(x + 1, y + -10, z + 5, Blocks.stone, 0, 3);
		world.setBlock(x + 9, y + -10, z + 5, Blocks.stone, 0, 3);
		world.setBlock(x + 10, y + -10, z + 5, Blocks.planks, 0, 3);
		world.setBlock(x + 12, y + -10, z + 5, Blocks.gold_block, 0, 3);
		world.setBlock(x + 16, y + -10, z + 5, Blocks.iron_block, 0, 3);
		world.setBlock(x + 24, y + -10, z + 5, Blocks.gold_block, 0, 3);
		world.setBlock(x + 25, y + -10, z + 5, Blocks.gold_block, 0, 3);
		world.setBlock(x + 26, y + -10, z + 5, Blocks.gold_block, 0, 3);
		world.setBlock(x + 27, y + -10, z + 5, Blocks.planks, 0, 3);
		world.setBlock(x + 28, y + -10, z + 5, Blocks.bedrock, 0, 3);
		world.setBlock(x + 0, y + -10, z + 6, Blocks.bedrock, 0, 3);
		world.setBlock(x + 1, y + -10, z + 6, Blocks.stone, 0, 3);
		world.setBlock(x + 9, y + -10, z + 6, Blocks.stone, 0, 3);
		world.setBlock(x + 10, y + -10, z + 6, Blocks.planks, 0, 3);
		world.setBlock(x + 11, y + -10, z + 6, Blocks.gold_block, 0, 3);
		world.setBlock(x + 16, y + -10, z + 6, Blocks.gold_block, 0, 3);
		world.setBlock(x + 25, y + -10, z + 6, Blocks.gold_block, 0, 3);
		world.setBlock(x + 26, y + -10, z + 6, Blocks.gold_block, 0, 3);
		world.setBlock(x + 27, y + -10, z + 6, Blocks.planks, 0, 3);
		world.setBlock(x + 28, y + -10, z + 6, Blocks.bedrock, 0, 3);
		world.setBlock(x + 0, y + -10, z + 7, Blocks.bedrock, 0, 3);
		world.setBlock(x + 1, y + -10, z + 7, Blocks.stone, 0, 3);
		world.setBlock(x + 9, y + -10, z + 7, Blocks.stone, 0, 3);
		world.setBlock(x + 10, y + -10, z + 7, Blocks.planks, 0, 3);
		world.setBlock(x + 26, y + -10, z + 7, Blocks.gold_block, 0, 3);
		world.setBlock(x + 27, y + -10, z + 7, Blocks.planks, 0, 3);
		world.setBlock(x + 28, y + -10, z + 7, Blocks.bedrock, 0, 3);
		world.setBlock(x + 0, y + -10, z + 8, Blocks.bedrock, 0, 3);
		world.setBlock(x + 1, y + -10, z + 8, Blocks.stone, 0, 3);
		world.setBlock(x + 9, y + -10, z + 8, Blocks.iron_door, 0, 3);
		world.setBlock(x + 27, y + -10, z + 8, Blocks.planks, 0, 3);
		world.setBlock(x + 28, y + -10, z + 8, Blocks.bedrock, 0, 3);
		world.setBlock(x + 0, y + -10, z + 9, Blocks.bedrock, 0, 3);
		world.setBlock(x + 1, y + -10, z + 9, Blocks.stone, 0, 3);
		world.setBlock(x + 9, y + -10, z + 9, Blocks.stone, 0, 3);
		world.setBlock(x + 10, y + -10, z + 9, Blocks.planks, 0, 3);
		world.setBlock(x + 19, y + -10, z + 9, Blocks.iron_block, 0, 3);
		world.setBlock(x + 27, y + -10, z + 9, Blocks.planks, 0, 3);
		world.setBlock(x + 28, y + -10, z + 9, Blocks.bedrock, 0, 3);
		world.setBlock(x + 0, y + -10, z + 10, Blocks.bedrock, 0, 3);
		world.setBlock(x + 1, y + -10, z + 10, Blocks.stone, 0, 3);
		world.setBlock(x + 9, y + -10, z + 10, Blocks.stone, 0, 3);
		world.setBlock(x + 10, y + -10, z + 10, Blocks.planks, 0, 3);
		world.setBlock(x + 18, y + -10, z + 10, Blocks.iron_block, 0, 3);
		world.setBlock(x + 20, y + -10, z + 10, Blocks.diamond_block, 0, 3);
		world.setBlock(x + 27, y + -10, z + 10, Blocks.planks, 0, 3);
		world.setBlock(x + 28, y + -10, z + 10, Blocks.bedrock, 0, 3);
		world.setBlock(x + 0, y + -10, z + 11, Blocks.bedrock, 0, 3);
		world.setBlock(x + 1, y + -10, z + 11, Blocks.stone, 0, 3);
		world.setBlock(x + 9, y + -10, z + 11, Blocks.stone, 0, 3);
		world.setBlock(x + 10, y + -10, z + 11, Blocks.planks, 0, 3);
		world.setBlock(x + 17, y + -10, z + 11, Blocks.iron_block, 0, 3);
		world.setBlock(x + 18, y + -10, z + 11, Blocks.gold_block, 0, 3);
		world.setBlock(x + 19, y + -10, z + 11, Blocks.diamond_block, 0, 3);
		world.setBlock(x + 20, y + -10, z + 11, Blocks.gold_block, 0, 3);
		world.setBlock(x + 27, y + -10, z + 11, Blocks.planks, 0, 3);
		world.setBlock(x + 28, y + -10, z + 11, Blocks.bedrock, 0, 3);
		world.setBlock(x + 0, y + -10, z + 12, Blocks.bedrock, 0, 3);
		world.setBlock(x + 1, y + -10, z + 12, Blocks.stone, 0, 3);
		world.setBlock(x + 2, y + -10, z + 12, Blocks.stone, 0, 3);
		world.setBlock(x + 3, y + -10, z + 12, Blocks.stone, 0, 3);
		world.setBlock(x + 4, y + -10, z + 12, Blocks.stone, 0, 3);
		world.setBlock(x + 5, y + -10, z + 12, Blocks.iron_door, 3, 3);
		world.setBlock(x + 6, y + -10, z + 12, Blocks.stone, 0, 3);
		world.setBlock(x + 7, y + -10, z + 12, Blocks.stone, 0, 3);
		world.setBlock(x + 8, y + -10, z + 12, Blocks.stone, 0, 3);
		world.setBlock(x + 9, y + -10, z + 12, Blocks.stone, 0, 3);
		world.setBlock(x + 10, y + -10, z + 12, Blocks.planks, 0, 3);
		world.setBlock(x + 16, y + -10, z + 12, Blocks.iron_block, 0, 3);
		world.setBlock(x + 17, y + -10, z + 12, Blocks.iron_block, 0, 3);
		world.setBlock(x + 18, y + -10, z + 12, Blocks.iron_block, 0, 3);
		world.setBlock(x + 19, y + -10, z + 12, Blocks.gold_block, 0, 3);
		world.setBlock(x + 20, y + -10, z + 12, Blocks.iron_block, 0, 3);
		world.setBlock(x + 27, y + -10, z + 12, Blocks.planks, 0, 3);
		world.setBlock(x + 28, y + -10, z + 12, Blocks.bedrock, 0, 3);
		world.setBlock(x + 0, y + -10, z + 13, Blocks.bedrock, 0, 3);
		world.setBlock(x + 1, y + -10, z + 13, Blocks.stone, 0, 3);
		world.setBlock(x + 9, y + -10, z + 13, Blocks.stone, 0, 3);
		world.setBlock(x + 10, y + -10, z + 13, Blocks.planks, 0, 3);
		world.setBlock(x + 18, y + -10, z + 13, Blocks.iron_block, 0, 3);
		world.setBlock(x + 19, y + -10, z + 13, Blocks.iron_block, 0, 3);
		world.setBlock(x + 27, y + -10, z + 13, Blocks.planks, 0, 3);
		world.setBlock(x + 28, y + -10, z + 13, Blocks.bedrock, 0, 3);
		world.setBlock(x + 0, y + -10, z + 14, Blocks.bedrock, 0, 3);
		world.setBlock(x + 1, y + -10, z + 14, Blocks.stone, 0, 3);
		world.setBlock(x + 9, y + -10, z + 14, Blocks.stone, 0, 3);
		world.setBlock(x + 10, y + -10, z + 14, Blocks.planks, 0, 3);
		world.setBlock(x + 19, y + -10, z + 14, Blocks.iron_block, 0, 3);
		world.setBlock(x + 27, y + -10, z + 14, Blocks.planks, 0, 3);
		world.setBlock(x + 28, y + -10, z + 14, Blocks.bedrock, 0, 3);
		world.setBlock(x + 0, y + -10, z + 15, Blocks.bedrock, 0, 3);
		world.setBlock(x + 1, y + -10, z + 15, Blocks.stone, 0, 3);
		world.setBlock(x + 9, y + -10, z + 15, Blocks.stone, 0, 3);
		world.setBlock(x + 10, y + -10, z + 15, Blocks.planks, 0, 3);
		world.setBlock(x + 26, y + -10, z + 15, Blocks.diamond_block, 0, 3);
		world.setBlock(x + 27, y + -10, z + 15, Blocks.planks, 0, 3);
		world.setBlock(x + 28, y + -10, z + 15, Blocks.bedrock, 0, 3);
		world.setBlock(x + 0, y + -10, z + 16, Blocks.bedrock, 0, 3);
		world.setBlock(x + 1, y + -10, z + 16, Blocks.stone, 0, 3);
		world.setBlock(x + 9, y + -10, z + 16, Blocks.stone, 0, 3);
		world.setBlock(x + 10, y + -10, z + 16, Blocks.planks, 0, 3);
		world.setBlock(x + 25, y + -10, z + 16, Blocks.diamond_block, 0, 3);
		world.setBlock(x + 27, y + -10, z + 16, Blocks.planks, 0, 3);
		world.setBlock(x + 28, y + -10, z + 16, Blocks.bedrock, 0, 3);
		world.setBlock(x + 0, y + -10, z + 17, Blocks.bedrock, 0, 3);
		world.setBlock(x + 1, y + -10, z + 17, Blocks.stone, 0, 3);
		world.setBlock(x + 9, y + -10, z + 17, Blocks.stone, 0, 3);
		world.setBlock(x + 10, y + -10, z + 17, Blocks.planks, 0, 3);
		world.setBlock(x + 11, y + -10, z + 17, Blocks.planks, 0, 3);
		world.setBlock(x + 12, y + -10, z + 17, Blocks.planks, 0, 3);
		world.setBlock(x + 13, y + -10, z + 17, Blocks.planks, 0, 3);
		world.setBlock(x + 14, y + -10, z + 17, Blocks.planks, 0, 3);
		world.setBlock(x + 15, y + -10, z + 17, Blocks.planks, 0, 3);
		world.setBlock(x + 16, y + -10, z + 17, Blocks.planks, 0, 3);
		world.setBlock(x + 17, y + -10, z + 17, Blocks.planks, 0, 3);
		world.setBlock(x + 18, y + -10, z + 17, Blocks.planks, 0, 3);
		world.setBlock(x + 19, y + -10, z + 17, Blocks.planks, 0, 3);
		world.setBlock(x + 20, y + -10, z + 17, Blocks.planks, 0, 3);
		world.setBlock(x + 21, y + -10, z + 17, Blocks.planks, 0, 3);
		world.setBlock(x + 22, y + -10, z + 17, Blocks.planks, 0, 3);
		world.setBlock(x + 23, y + -10, z + 17, Blocks.planks, 0, 3);
		world.setBlock(x + 24, y + -10, z + 17, Blocks.planks, 0, 3);
		world.setBlock(x + 25, y + -10, z + 17, Blocks.planks, 0, 3);
		world.setBlock(x + 26, y + -10, z + 17, Blocks.planks, 0, 3);
		world.setBlock(x + 27, y + -10, z + 17, Blocks.planks, 0, 3);
		world.setBlock(x + 28, y + -10, z + 17, Blocks.bedrock, 0, 3);
		world.setBlock(x + 0, y + -10, z + 18, Blocks.bedrock, 0, 3);
		world.setBlock(x + 1, y + -10, z + 18, Blocks.stone, 0, 3);
		world.setBlock(x + 9, y + -10, z + 18, Blocks.stone, 0, 3);
		world.setBlock(x + 10, y + -10, z + 18, Blocks.bedrock, 0, 3);
		world.setBlock(x + 11, y + -10, z + 18, Blocks.bedrock, 0, 3);
		world.setBlock(x + 12, y + -10, z + 18, Blocks.bedrock, 0, 3);
		world.setBlock(x + 13, y + -10, z + 18, Blocks.bedrock, 0, 3);
		world.setBlock(x + 14, y + -10, z + 18, Blocks.bedrock, 0, 3);
		world.setBlock(x + 15, y + -10, z + 18, Blocks.bedrock, 0, 3);
		world.setBlock(x + 16, y + -10, z + 18, Blocks.bedrock, 0, 3);
		world.setBlock(x + 17, y + -10, z + 18, Blocks.bedrock, 0, 3);
		world.setBlock(x + 18, y + -10, z + 18, Blocks.bedrock, 0, 3);
		world.setBlock(x + 19, y + -10, z + 18, Blocks.bedrock, 0, 3);
		world.setBlock(x + 20, y + -10, z + 18, Blocks.bedrock, 0, 3);
		world.setBlock(x + 21, y + -10, z + 18, Blocks.bedrock, 0, 3);
		world.setBlock(x + 22, y + -10, z + 18, Blocks.bedrock, 0, 3);
		world.setBlock(x + 23, y + -10, z + 18, Blocks.bedrock, 0, 3);
		world.setBlock(x + 24, y + -10, z + 18, Blocks.bedrock, 0, 3);
		world.setBlock(x + 25, y + -10, z + 18, Blocks.bedrock, 0, 3);
		world.setBlock(x + 26, y + -10, z + 18, Blocks.bedrock, 0, 3);
		world.setBlock(x + 27, y + -10, z + 18, Blocks.bedrock, 0, 3);
		world.setBlock(x + 28, y + -10, z + 18, Blocks.bedrock, 0, 3);
		world.setBlock(x + 0, y + -10, z + 19, Blocks.bedrock, 0, 3);
		world.setBlock(x + 1, y + -10, z + 19, Blocks.stone, 0, 3);
		world.setBlock(x + 9, y + -10, z + 19, Blocks.stone, 0, 3);
		world.setBlock(x + 10, y + -10, z + 19, Blocks.bedrock, 0, 3);
		world.setBlock(x + 0, y + -10, z + 20, Blocks.bedrock, 0, 3);
		world.setBlock(x + 1, y + -10, z + 20, Blocks.stone, 0, 3);
		world.setBlock(x + 2, y + -10, z + 20, Blocks.stone, 0, 3);
		world.setBlock(x + 3, y + -10, z + 20, Blocks.stone, 0, 3);
		world.setBlock(x + 4, y + -10, z + 20, Blocks.stone, 0, 3);
		world.setBlock(x + 5, y + -10, z + 20, Blocks.iron_door, 3, 3);
		world.setBlock(x + 6, y + -10, z + 20, Blocks.stone, 0, 3);
		world.setBlock(x + 7, y + -10, z + 20, Blocks.stone, 0, 3);
		world.setBlock(x + 8, y + -10, z + 20, Blocks.stone, 0, 3);
		world.setBlock(x + 9, y + -10, z + 20, Blocks.stone, 0, 3);
		world.setBlock(x + 10, y + -10, z + 20, Blocks.bedrock, 0, 3);
		world.setBlock(x + 0, y + -10, z + 21, Blocks.bedrock, 0, 3);
		world.setBlock(x + 1, y + -10, z + 21, Blocks.stone, 0, 3);
		world.setBlock(x + 9, y + -10, z + 21, Blocks.stone, 0, 3);
		world.setBlock(x + 10, y + -10, z + 21, Blocks.bedrock, 0, 3);
		world.setBlock(x + 0, y + -10, z + 22, Blocks.bedrock, 0, 3);
		world.setBlock(x + 1, y + -10, z + 22, Blocks.stone, 0, 3);
		world.setBlock(x + 9, y + -10, z + 22, Blocks.stone, 0, 3);
		world.setBlock(x + 10, y + -10, z + 22, Blocks.bedrock, 0, 3);
		world.setBlock(x + 0, y + -10, z + 23, Blocks.bedrock, 0, 3);
		world.setBlock(x + 1, y + -10, z + 23, Blocks.stone, 0, 3);
		world.setBlock(x + 9, y + -10, z + 23, Blocks.stone, 0, 3);
		world.setBlock(x + 10, y + -10, z + 23, Blocks.bedrock, 0, 3);
		world.setBlock(x + 0, y + -10, z + 24, Blocks.bedrock, 0, 3);
		world.setBlock(x + 1, y + -10, z + 24, Blocks.stone, 0, 3);
		world.setBlock(x + 9, y + -10, z + 24, Blocks.stone, 0, 3);
		world.setBlock(x + 10, y + -10, z + 24, Blocks.bedrock, 0, 3);
		world.setBlock(x + 0, y + -10, z + 25, Blocks.bedrock, 0, 3);
		world.setBlock(x + 1, y + -10, z + 25, Blocks.stone, 0, 3);
		world.setBlock(x + 9, y + -10, z + 25, Blocks.stone, 0, 3);
		world.setBlock(x + 10, y + -10, z + 25, Blocks.bedrock, 0, 3);
		world.setBlock(x + 0, y + -10, z + 26, Blocks.bedrock, 0, 3);
		world.setBlock(x + 1, y + -10, z + 26, Blocks.stone, 0, 3);
		world.setBlock(x + 9, y + -10, z + 26, Blocks.stone, 0, 3);
		world.setBlock(x + 10, y + -10, z + 26, Blocks.bedrock, 0, 3);
		world.setBlock(x + 0, y + -10, z + 27, Blocks.bedrock, 0, 3);
		world.setBlock(x + 1, y + -10, z + 27, Blocks.stone, 0, 3);
		world.setBlock(x + 9, y + -10, z + 27, Blocks.stone, 0, 3);
		world.setBlock(x + 10, y + -10, z + 27, Blocks.bedrock, 0, 3);
		world.setBlock(x + 0, y + -10, z + 28, Blocks.bedrock, 0, 3);
		world.setBlock(x + 1, y + -10, z + 28, Blocks.stone, 0, 3);
		world.setBlock(x + 2, y + -10, z + 28, Blocks.stone, 0, 3);
		world.setBlock(x + 3, y + -10, z + 28, Blocks.stone, 0, 3);
		world.setBlock(x + 4, y + -10, z + 28, Blocks.stone, 0, 3);
		world.setBlock(x + 5, y + -10, z + 28, Blocks.iron_door, 3, 3);
		world.setBlock(x + 6, y + -10, z + 28, Blocks.stone, 0, 3);
		world.setBlock(x + 7, y + -10, z + 28, Blocks.stone, 0, 3);
		world.setBlock(x + 8, y + -10, z + 28, Blocks.stone, 0, 3);
		world.setBlock(x + 9, y + -10, z + 28, Blocks.stone, 0, 3);
		world.setBlock(x + 10, y + -10, z + 28, Blocks.bedrock, 0, 3);
		world.setBlock(x + 0, y + -10, z + 29, Blocks.bedrock, 0, 3);
		world.setBlock(x + 1, y + -10, z + 29, Blocks.stone, 0, 3);
		world.setBlock(x + 9, y + -10, z + 29, Blocks.stone, 0, 3);
		world.setBlock(x + 10, y + -10, z + 29, Blocks.bedrock, 0, 3);
		world.setBlock(x + 0, y + -10, z + 30, Blocks.bedrock, 0, 3);
		world.setBlock(x + 1, y + -10, z + 30, Blocks.stone, 0, 3);
		world.setBlock(x + 9, y + -10, z + 30, Blocks.stone, 0, 3);
		world.setBlock(x + 10, y + -10, z + 30, Blocks.bedrock, 0, 3);
		world.setBlock(x + 0, y + -10, z + 31, Blocks.bedrock, 0, 3);
		world.setBlock(x + 1, y + -10, z + 31, Blocks.stone, 0, 3);
		world.setBlock(x + 9, y + -10, z + 31, Blocks.stone, 0, 3);
		world.setBlock(x + 10, y + -10, z + 31, Blocks.bedrock, 0, 3);
		world.setBlock(x + 0, y + -10, z + 32, Blocks.bedrock, 0, 3);
		world.setBlock(x + 1, y + -10, z + 32, Blocks.stone, 0, 3);
		world.setBlock(x + 9, y + -10, z + 32, Blocks.stone, 0, 3);
		world.setBlock(x + 10, y + -10, z + 32, Blocks.bedrock, 0, 3);
		world.setBlock(x + 0, y + -10, z + 33, Blocks.bedrock, 0, 3);
		world.setBlock(x + 1, y + -10, z + 33, Blocks.stone, 0, 3);
		world.setBlock(x + 9, y + -10, z + 33, Blocks.stone, 0, 3);
		world.setBlock(x + 10, y + -10, z + 33, Blocks.bedrock, 0, 3);
		world.setBlock(x + 0, y + -10, z + 34, Blocks.bedrock, 0, 3);
		world.setBlock(x + 1, y + -10, z + 34, Blocks.stone, 0, 3);
		world.setBlock(x + 9, y + -10, z + 34, Blocks.stone, 0, 3);
		world.setBlock(x + 10, y + -10, z + 34, Blocks.bedrock, 0, 3);
		world.setBlock(x + 0, y + -10, z + 35, Blocks.bedrock, 0, 3);
		world.setBlock(x + 1, y + -10, z + 35, Blocks.stone, 0, 3);
		world.setBlock(x + 9, y + -10, z + 35, Blocks.stone, 0, 3);
		world.setBlock(x + 10, y + -10, z + 35, Blocks.bedrock, 0, 3);
		world.setBlock(x + 0, y + -10, z + 36, Blocks.bedrock, 0, 3);
		world.setBlock(x + 1, y + -10, z + 36, Blocks.stone, 0, 3);
		world.setBlock(x + 2, y + -10, z + 36, Blocks.stone, 0, 3);
		world.setBlock(x + 3, y + -10, z + 36, Blocks.stone, 0, 3);
		world.setBlock(x + 4, y + -10, z + 36, Blocks.stone, 0, 3);
		world.setBlock(x + 5, y + -10, z + 36, Blocks.iron_door, 3, 3);
		world.setBlock(x + 6, y + -10, z + 36, Blocks.stone, 0, 3);
		world.setBlock(x + 7, y + -10, z + 36, Blocks.stone, 0, 3);
		world.setBlock(x + 8, y + -10, z + 36, Blocks.stone, 0, 3);
		world.setBlock(x + 9, y + -10, z + 36, Blocks.stone, 0, 3);
		world.setBlock(x + 10, y + -10, z + 36, Blocks.bedrock, 0, 3);
		world.setBlock(x + 0, y + -10, z + 37, Blocks.bedrock, 0, 3);
		world.setBlock(x + 1, y + -10, z + 37, Blocks.stone, 0, 3);
		world.setBlock(x + 9, y + -10, z + 37, Blocks.stone, 0, 3);
		world.setBlock(x + 10, y + -10, z + 37, Blocks.bedrock, 0, 3);
		world.setBlock(x + 0, y + -10, z + 38, Blocks.bedrock, 0, 3);
		world.setBlock(x + 1, y + -10, z + 38, Blocks.stone, 0, 3);
		world.setBlock(x + 9, y + -10, z + 38, Blocks.stone, 0, 3);
		world.setBlock(x + 10, y + -10, z + 38, Blocks.bedrock, 0, 3);
		world.setBlock(x + 0, y + -10, z + 39, Blocks.bedrock, 0, 3);
		world.setBlock(x + 1, y + -10, z + 39, Blocks.stone, 0, 3);
		world.setBlock(x + 9, y + -10, z + 39, Blocks.stone, 0, 3);
		world.setBlock(x + 10, y + -10, z + 39, Blocks.bedrock, 0, 3);
		world.setBlock(x + 0, y + -10, z + 40, Blocks.bedrock, 0, 3);
		world.setBlock(x + 1, y + -10, z + 40, Blocks.stone, 0, 3);
		world.setBlock(x + 9, y + -10, z + 40, Blocks.stone, 0, 3);
		world.setBlock(x + 10, y + -10, z + 40, Blocks.bedrock, 0, 3);
		world.setBlock(x + 0, y + -10, z + 41, Blocks.bedrock, 0, 3);
		world.setBlock(x + 1, y + -10, z + 41, Blocks.stone, 0, 3);
		world.setBlock(x + 9, y + -10, z + 41, Blocks.stone, 0, 3);
		world.setBlock(x + 10, y + -10, z + 41, Blocks.bedrock, 0, 3);
		world.setBlock(x + 0, y + -10, z + 42, Blocks.bedrock, 0, 3);
		world.setBlock(x + 1, y + -10, z + 42, Blocks.stone, 0, 3);
		world.setBlock(x + 9, y + -10, z + 42, Blocks.stone, 0, 3);
		world.setBlock(x + 10, y + -10, z + 42, Blocks.bedrock, 0, 3);
		world.setBlock(x + 0, y + -10, z + 43, Blocks.bedrock, 0, 3);
		world.setBlock(x + 1, y + -10, z + 43, Blocks.stone, 0, 3);
		world.setBlock(x + 9, y + -10, z + 43, Blocks.stone, 0, 3);
		world.setBlock(x + 10, y + -10, z + 43, Blocks.bedrock, 0, 3);
		world.setBlock(x + 0, y + -10, z + 44, Blocks.bedrock, 0, 3);
		world.setBlock(x + 1, y + -10, z + 44, Blocks.stone, 0, 3);
		world.setBlock(x + 2, y + -10, z + 44, Blocks.stone, 0, 3);
		world.setBlock(x + 3, y + -10, z + 44, Blocks.stone, 0, 3);
		world.setBlock(x + 4, y + -10, z + 44, Blocks.stone, 0, 3);
		world.setBlock(x + 5, y + -10, z + 44, Blocks.iron_door, 3, 3);
		world.setBlock(x + 6, y + -10, z + 44, Blocks.stone, 0, 3);
		world.setBlock(x + 7, y + -10, z + 44, Blocks.stone, 0, 3);
		world.setBlock(x + 8, y + -10, z + 44, Blocks.stone, 0, 3);
		world.setBlock(x + 9, y + -10, z + 44, Blocks.stone, 0, 3);
		world.setBlock(x + 10, y + -10, z + 44, Blocks.bedrock, 0, 3);
		world.setBlock(x + 0, y + -10, z + 45, Blocks.bedrock, 0, 3);
		world.setBlock(x + 1, y + -10, z + 45, Blocks.stone, 0, 3);
		world.setBlock(x + 9, y + -10, z + 45, Blocks.stone, 0, 3);
		world.setBlock(x + 10, y + -10, z + 45, Blocks.bedrock, 0, 3);
		world.setBlock(x + 0, y + -10, z + 46, Blocks.bedrock, 0, 3);
		world.setBlock(x + 1, y + -10, z + 46, Blocks.stone, 0, 3);
		world.setBlock(x + 9, y + -10, z + 46, Blocks.stone, 0, 3);
		world.setBlock(x + 10, y + -10, z + 46, Blocks.bedrock, 0, 3);
		world.setBlock(x + 0, y + -10, z + 47, Blocks.bedrock, 0, 3);
		world.setBlock(x + 1, y + -10, z + 47, Blocks.stone, 0, 3);
		world.setBlock(x + 9, y + -10, z + 47, Blocks.stone, 0, 3);
		world.setBlock(x + 10, y + -10, z + 47, Blocks.bedrock, 0, 3);
		world.setBlock(x + 0, y + -10, z + 48, Blocks.bedrock, 0, 3);
		world.setBlock(x + 1, y + -10, z + 48, Blocks.stone, 0, 3);
		world.setBlock(x + 9, y + -10, z + 48, Blocks.stone, 0, 3);
		world.setBlock(x + 10, y + -10, z + 48, Blocks.bedrock, 0, 3);
		world.setBlock(x + 0, y + -10, z + 49, Blocks.bedrock, 0, 3);
		world.setBlock(x + 1, y + -10, z + 49, Blocks.stone, 0, 3);
		world.setBlock(x + 9, y + -10, z + 49, Blocks.stone, 0, 3);
		world.setBlock(x + 10, y + -10, z + 49, Blocks.bedrock, 0, 3);
		world.setBlock(x + 0, y + -10, z + 50, Blocks.bedrock, 0, 3);
		world.setBlock(x + 1, y + -10, z + 50, Blocks.stone, 0, 3);
		world.setBlock(x + 9, y + -10, z + 50, Blocks.stone, 0, 3);
		world.setBlock(x + 10, y + -10, z + 50, Blocks.bedrock, 0, 3);
		world.setBlock(x + 0, y + -10, z + 51, Blocks.bedrock, 0, 3);
		world.setBlock(x + 1, y + -10, z + 51, Blocks.stone, 0, 3);
		world.setBlock(x + 9, y + -10, z + 51, Blocks.stone, 0, 3);
		world.setBlock(x + 10, y + -10, z + 51, Blocks.bedrock, 0, 3);
		world.setBlock(x + 0, y + -10, z + 52, Blocks.bedrock, 0, 3);
		world.setBlock(x + 1, y + -10, z + 52, Blocks.stone, 0, 3);
		world.setBlock(x + 2, y + -10, z + 52, Blocks.stone, 0, 3);
		world.setBlock(x + 3, y + -10, z + 52, Blocks.stone, 0, 3);
		world.setBlock(x + 4, y + -10, z + 52, Blocks.stone, 0, 3);
		world.setBlock(x + 5, y + -10, z + 52, Blocks.iron_door, 3, 3);
		world.setBlock(x + 6, y + -10, z + 52, Blocks.stone, 0, 3);
		world.setBlock(x + 7, y + -10, z + 52, Blocks.stone, 0, 3);
		world.setBlock(x + 8, y + -10, z + 52, Blocks.stone, 0, 3);
		world.setBlock(x + 9, y + -10, z + 52, Blocks.stone, 0, 3);
		world.setBlock(x + 10, y + -10, z + 52, Blocks.stone, 0, 3);
		world.setBlock(x + 11, y + -10, z + 52, Blocks.stone, 0, 3);
		world.setBlock(x + 12, y + -10, z + 52, Blocks.stone, 0, 3);
		world.setBlock(x + 13, y + -10, z + 52, Blocks.stone, 0, 3);
		world.setBlock(x + 14, y + -10, z + 52, Blocks.stone, 0, 3);
		world.setBlock(x + 15, y + -10, z + 52, Blocks.stone, 0, 3);
		world.setBlock(x + 16, y + -10, z + 52, Blocks.stone, 0, 3);
		world.setBlock(x + 17, y + -10, z + 52, Blocks.stone, 0, 3);
		world.setBlock(x + 0, y + -10, z + 53, Blocks.bedrock, 0, 3);
		world.setBlock(x + 1, y + -10, z + 53, Blocks.stone, 0, 3);
		world.setBlock(x + 9, y + -10, z + 53, Blocks.stone, 0, 3);
		world.setBlock(x + 17, y + -10, z + 53, Blocks.stone, 0, 3);
		world.setBlock(x + 0, y + -10, z + 54, Blocks.bedrock, 0, 3);
		world.setBlock(x + 1, y + -10, z + 54, Blocks.stone, 0, 3);
		world.setBlock(x + 9, y + -10, z + 54, Blocks.stone, 0, 3);
		world.setBlock(x + 17, y + -10, z + 54, Blocks.stone, 0, 3);
		world.setBlock(x + 0, y + -10, z + 55, Blocks.bedrock, 0, 3);
		world.setBlock(x + 1, y + -10, z + 55, Blocks.stone, 0, 3);
		world.setBlock(x + 9, y + -10, z + 55, Blocks.stone, 0, 3);
		world.setBlock(x + 12, y + -10, z + 55, Blocks.stone_slab, 11, 3);
		world.setBlock(x + 17, y + -10, z + 55, Blocks.stone, 0, 3);
		world.setBlock(x + 0, y + -10, z + 56, Blocks.bedrock, 0, 3);
		world.setBlock(x + 1, y + -10, z + 56, Blocks.stone, 0, 3);
		world.setBlock(x + 9, y + -10, z + 56, Blocks.iron_door, 2, 3);
		world.setBlock(x + 12, y + -10, z + 56, Blocks.stone_stairs, 3, 3);
		world.setBlock(x + 13, y + -10, z + 56, Blocks.cobblestone, 0, 3);
		world.setBlock(x + 17, y + -10, z + 56, Blocks.stone, 0, 3);
		world.setBlock(x + 0, y + -10, z + 57, Blocks.bedrock, 0, 3);
		world.setBlock(x + 1, y + -10, z + 57, Blocks.stone, 0, 3);
		world.setBlock(x + 9, y + -10, z + 57, Blocks.stone, 0, 3);
		world.setBlock(x + 12, y + -10, z + 57, Blocks.stone_slab, 3, 3);
		world.setBlock(x + 17, y + -10, z + 57, Blocks.stone, 0, 3);
		world.setBlock(x + 0, y + -10, z + 58, Blocks.bedrock, 0, 3);
		world.setBlock(x + 1, y + -10, z + 58, Blocks.stone, 0, 3);
		world.setBlock(x + 9, y + -10, z + 58, Blocks.stone, 0, 3);
		world.setBlock(x + 17, y + -10, z + 58, Blocks.stone, 0, 3);
		world.setBlock(x + 0, y + -10, z + 59, Blocks.bedrock, 0, 3);
		world.setBlock(x + 1, y + -10, z + 59, Blocks.stone, 0, 3);
		world.setBlock(x + 9, y + -10, z + 59, Blocks.stone, 0, 3);
		world.setBlock(x + 17, y + -10, z + 59, Blocks.stone, 0, 3);
		world.setBlock(x + 0, y + -10, z + 60, Blocks.bedrock, 0, 3);
		world.setBlock(x + 1, y + -10, z + 60, Blocks.stone, 0, 3);
		world.setBlock(x + 2, y + -10, z + 60, Blocks.stone, 0, 3);
		world.setBlock(x + 3, y + -10, z + 60, Blocks.stone, 0, 3);
		world.setBlock(x + 4, y + -10, z + 60, Blocks.stone, 0, 3);
		world.setBlock(x + 5, y + -10, z + 60, Blocks.stone, 0, 3);
		world.setBlock(x + 6, y + -10, z + 60, Blocks.stone, 0, 3);
		world.setBlock(x + 7, y + -10, z + 60, Blocks.stone, 0, 3);
		world.setBlock(x + 8, y + -10, z + 60, Blocks.stone, 0, 3);
		world.setBlock(x + 9, y + -10, z + 60, Blocks.stone, 0, 3);
		world.setBlock(x + 10, y + -10, z + 60, Blocks.stone, 0, 3);
		world.setBlock(x + 11, y + -10, z + 60, Blocks.stone, 0, 3);
		world.setBlock(x + 12, y + -10, z + 60, Blocks.stone, 0, 3);
		world.setBlock(x + 13, y + -10, z + 60, Blocks.stone, 0, 3);
		world.setBlock(x + 14, y + -10, z + 60, Blocks.stone, 0, 3);
		world.setBlock(x + 15, y + -10, z + 60, Blocks.stone, 0, 3);
		world.setBlock(x + 16, y + -10, z + 60, Blocks.stone, 0, 3);
		world.setBlock(x + 17, y + -10, z + 60, Blocks.stone, 0, 3);
		world.setBlock(x + 0, y + -10, z + 61, Blocks.bedrock, 0, 3);
		world.setBlock(x + 1, y + -10, z + 61, Blocks.bedrock, 0, 3);
		world.setBlock(x + 2, y + -10, z + 61, Blocks.bedrock, 0, 3);
		world.setBlock(x + 3, y + -10, z + 61, Blocks.bedrock, 0, 3);
		world.setBlock(x + 4, y + -10, z + 61, Blocks.bedrock, 0, 3);
		world.setBlock(x + 5, y + -10, z + 61, Blocks.bedrock, 0, 3);
		world.setBlock(x + 6, y + -10, z + 61, Blocks.bedrock, 0, 3);
		world.setBlock(x + 7, y + -10, z + 61, Blocks.bedrock, 0, 3);
		world.setBlock(x + 8, y + -10, z + 61, Blocks.bedrock, 0, 3);
		world.setBlock(x + 9, y + -10, z + 61, Blocks.bedrock, 0, 3);
		world.setBlock(x + 0, y + -9, z + 3, Blocks.bedrock, 0, 3);
		world.setBlock(x + 1, y + -9, z + 3, Blocks.bedrock, 0, 3);
		world.setBlock(x + 2, y + -9, z + 3, Blocks.bedrock, 0, 3);
		world.setBlock(x + 3, y + -9, z + 3, Blocks.bedrock, 0, 3);
		world.setBlock(x + 4, y + -9, z + 3, Blocks.bedrock, 0, 3);
		world.setBlock(x + 5, y + -9, z + 3, Blocks.bedrock, 0, 3);
		world.setBlock(x + 6, y + -9, z + 3, Blocks.bedrock, 0, 3);
		world.setBlock(x + 7, y + -9, z + 3, Blocks.bedrock, 0, 3);
		world.setBlock(x + 8, y + -9, z + 3, Blocks.bedrock, 0, 3);
		world.setBlock(x + 9, y + -9, z + 3, Blocks.bedrock, 0, 3);
		world.setBlock(x + 10, y + -9, z + 3, Blocks.bedrock, 0, 3);
		world.setBlock(x + 11, y + -9, z + 3, Blocks.bedrock, 0, 3);
		world.setBlock(x + 12, y + -9, z + 3, Blocks.bedrock, 0, 3);
		world.setBlock(x + 13, y + -9, z + 3, Blocks.bedrock, 0, 3);
		world.setBlock(x + 14, y + -9, z + 3, Blocks.bedrock, 0, 3);
		world.setBlock(x + 15, y + -9, z + 3, Blocks.bedrock, 0, 3);
		world.setBlock(x + 16, y + -9, z + 3, Blocks.bedrock, 0, 3);
		world.setBlock(x + 17, y + -9, z + 3, Blocks.bedrock, 0, 3);
		world.setBlock(x + 18, y + -9, z + 3, Blocks.bedrock, 0, 3);
		world.setBlock(x + 19, y + -9, z + 3, Blocks.bedrock, 0, 3);
		world.setBlock(x + 20, y + -9, z + 3, Blocks.bedrock, 0, 3);
		world.setBlock(x + 21, y + -9, z + 3, Blocks.bedrock, 0, 3);
		world.setBlock(x + 22, y + -9, z + 3, Blocks.bedrock, 0, 3);
		world.setBlock(x + 23, y + -9, z + 3, Blocks.bedrock, 0, 3);
		world.setBlock(x + 24, y + -9, z + 3, Blocks.bedrock, 0, 3);
		world.setBlock(x + 25, y + -9, z + 3, Blocks.bedrock, 0, 3);
		world.setBlock(x + 26, y + -9, z + 3, Blocks.bedrock, 0, 3);
		world.setBlock(x + 27, y + -9, z + 3, Blocks.bedrock, 0, 3);
		world.setBlock(x + 28, y + -9, z + 3, Blocks.bedrock, 0, 3);
		world.setBlock(x + 0, y + -9, z + 4, Blocks.bedrock, 0, 3);
		world.setBlock(x + 1, y + -9, z + 4, Blocks.stone, 0, 3);
		world.setBlock(x + 2, y + -9, z + 4, Blocks.stone, 0, 3);
		world.setBlock(x + 3, y + -9, z + 4, Blocks.stone, 0, 3);
		world.setBlock(x + 4, y + -9, z + 4, Blocks.stone, 0, 3);
		world.setBlock(x + 5, y + -9, z + 4, Blocks.stone, 0, 3);
		world.setBlock(x + 6, y + -9, z + 4, Blocks.stone, 0, 3);
		world.setBlock(x + 7, y + -9, z + 4, Blocks.stone, 0, 3);
		world.setBlock(x + 8, y + -9, z + 4, Blocks.stone, 0, 3);
		world.setBlock(x + 9, y + -9, z + 4, Blocks.stone, 0, 3);
		world.setBlock(x + 10, y + -9, z + 4, Blocks.planks, 0, 3);
		world.setBlock(x + 11, y + -9, z + 4, Blocks.planks, 0, 3);
		world.setBlock(x + 12, y + -9, z + 4, Blocks.planks, 0, 3);
		world.setBlock(x + 13, y + -9, z + 4, Blocks.planks, 0, 3);
		world.setBlock(x + 14, y + -9, z + 4, Blocks.planks, 0, 3);
		world.setBlock(x + 15, y + -9, z + 4, Blocks.planks, 0, 3);
		world.setBlock(x + 16, y + -9, z + 4, Blocks.planks, 0, 3);
		world.setBlock(x + 17, y + -9, z + 4, Blocks.planks, 0, 3);
		world.setBlock(x + 18, y + -9, z + 4, Blocks.planks, 0, 3);
		world.setBlock(x + 19, y + -9, z + 4, Blocks.planks, 0, 3);
		world.setBlock(x + 20, y + -9, z + 4, Blocks.planks, 0, 3);
		world.setBlock(x + 21, y + -9, z + 4, Blocks.planks, 0, 3);
		world.setBlock(x + 22, y + -9, z + 4, Blocks.planks, 0, 3);
		world.setBlock(x + 23, y + -9, z + 4, Blocks.planks, 0, 3);
		world.setBlock(x + 24, y + -9, z + 4, Blocks.planks, 0, 3);
		world.setBlock(x + 25, y + -9, z + 4, Blocks.planks, 0, 3);
		world.setBlock(x + 26, y + -9, z + 4, Blocks.planks, 0, 3);
		world.setBlock(x + 27, y + -9, z + 4, Blocks.planks, 0, 3);
		world.setBlock(x + 28, y + -9, z + 4, Blocks.bedrock, 0, 3);
		world.setBlock(x + 0, y + -9, z + 5, Blocks.bedrock, 0, 3);
		world.setBlock(x + 1, y + -9, z + 5, Blocks.stone, 0, 3);
		world.setBlock(x + 9, y + -9, z + 5, Blocks.stone, 0, 3);
		world.setBlock(x + 10, y + -9, z + 5, Blocks.planks, 0, 3);
		world.setBlock(x + 11, y + -9, z + 5, Blocks.diamond_block, 0, 3);
		world.setBlock(x + 16, y + -9, z + 5, Blocks.iron_block, 0, 3);
		world.setBlock(x + 25, y + -9, z + 5, Blocks.gold_block, 0, 3);
		world.setBlock(x + 26, y + -9, z + 5, Blocks.gold_block, 0, 3);
		world.setBlock(x + 27, y + -9, z + 5, Blocks.planks, 0, 3);
		world.setBlock(x + 28, y + -9, z + 5, Blocks.bedrock, 0, 3);
		world.setBlock(x + 0, y + -9, z + 6, Blocks.bedrock, 0, 3);
		world.setBlock(x + 1, y + -9, z + 6, Blocks.stone, 0, 3);
		world.setBlock(x + 9, y + -9, z + 6, Blocks.stone, 0, 3);
		world.setBlock(x + 10, y + -9, z + 6, Blocks.planks, 0, 3);
		world.setBlock(x + 26, y + -9, z + 6, Blocks.gold_block, 0, 3);
		world.setBlock(x + 27, y + -9, z + 6, Blocks.planks, 0, 3);
		world.setBlock(x + 28, y + -9, z + 6, Blocks.bedrock, 0, 3);
		world.setBlock(x + 0, y + -9, z + 7, Blocks.bedrock, 0, 3);
		world.setBlock(x + 1, y + -9, z + 7, Blocks.stone, 0, 3);
		world.setBlock(x + 9, y + -9, z + 7, Blocks.stone, 0, 3);
		world.setBlock(x + 10, y + -9, z + 7, Blocks.planks, 0, 3);
		world.setBlock(x + 27, y + -9, z + 7, Blocks.planks, 0, 3);
		world.setBlock(x + 28, y + -9, z + 7, Blocks.bedrock, 0, 3);
		world.setBlock(x + 0, y + -9, z + 8, Blocks.bedrock, 0, 3);
		world.setBlock(x + 1, y + -9, z + 8, Blocks.stone, 0, 3);
		world.setBlock(x + 9, y + -9, z + 8, Blocks.iron_door, 8, 3);
		world.setBlock(x + 27, y + -9, z + 8, Blocks.planks, 0, 3);
		world.setBlock(x + 28, y + -9, z + 8, Blocks.bedrock, 0, 3);
		world.setBlock(x + 0, y + -9, z + 9, Blocks.bedrock, 0, 3);
		world.setBlock(x + 1, y + -9, z + 9, Blocks.stone, 0, 3);
		world.setBlock(x + 9, y + -9, z + 9, Blocks.stone, 0, 3);
		world.setBlock(x + 10, y + -9, z + 9, Blocks.planks, 0, 3);
		world.setBlock(x + 27, y + -9, z + 9, Blocks.planks, 0, 3);
		world.setBlock(x + 28, y + -9, z + 9, Blocks.bedrock, 0, 3);
		world.setBlock(x + 0, y + -9, z + 10, Blocks.bedrock, 0, 3);
		world.setBlock(x + 1, y + -9, z + 10, Blocks.stone, 0, 3);
		world.setBlock(x + 9, y + -9, z + 10, Blocks.stone, 0, 3);
		world.setBlock(x + 10, y + -9, z + 10, Blocks.planks, 0, 3);
		world.setBlock(x + 19, y + -9, z + 10, Blocks.iron_block, 0, 3);
		world.setBlock(x + 27, y + -9, z + 10, Blocks.planks, 0, 3);
		world.setBlock(x + 28, y + -9, z + 10, Blocks.bedrock, 0, 3);
		world.setBlock(x + 0, y + -9, z + 11, Blocks.bedrock, 0, 3);
		world.setBlock(x + 1, y + -9, z + 11, Blocks.stone, 0, 3);
		world.setBlock(x + 9, y + -9, z + 11, Blocks.stone, 0, 3);
		world.setBlock(x + 10, y + -9, z + 11, Blocks.planks, 0, 3);
		world.setBlock(x + 18, y + -9, z + 11, Blocks.iron_block, 0, 3);
		world.setBlock(x + 19, y + -9, z + 11, Blocks.gold_block, 0, 3);
		world.setBlock(x + 27, y + -9, z + 11, Blocks.planks, 0, 3);
		world.setBlock(x + 28, y + -9, z + 11, Blocks.bedrock, 0, 3);
		world.setBlock(x + 0, y + -9, z + 12, Blocks.bedrock, 0, 3);
		world.setBlock(x + 1, y + -9, z + 12, Blocks.stone, 0, 3);
		world.setBlock(x + 2, y + -9, z + 12, Blocks.stone, 0, 3);
		world.setBlock(x + 3, y + -9, z + 12, Blocks.stone, 0, 3);
		world.setBlock(x + 4, y + -9, z + 12, Blocks.stone, 0, 3);
		world.setBlock(x + 5, y + -9, z + 12, Blocks.iron_door, 8, 3);
		world.setBlock(x + 6, y + -9, z + 12, Blocks.stone, 0, 3);
		world.setBlock(x + 7, y + -9, z + 12, Blocks.stone, 0, 3);
		world.setBlock(x + 8, y + -9, z + 12, Blocks.stone, 0, 3);
		world.setBlock(x + 9, y + -9, z + 12, Blocks.stone, 0, 3);
		world.setBlock(x + 10, y + -9, z + 12, Blocks.planks, 0, 3);
		world.setBlock(x + 19, y + -9, z + 12, Blocks.gold_block, 0, 3);
		world.setBlock(x + 27, y + -9, z + 12, Blocks.planks, 0, 3);
		world.setBlock(x + 28, y + -9, z + 12, Blocks.bedrock, 0, 3);
		world.setBlock(x + 0, y + -9, z + 13, Blocks.bedrock, 0, 3);
		world.setBlock(x + 1, y + -9, z + 13, Blocks.stone, 0, 3);
		world.setBlock(x + 9, y + -9, z + 13, Blocks.stone, 0, 3);
		world.setBlock(x + 10, y + -9, z + 13, Blocks.planks, 0, 3);
		world.setBlock(x + 27, y + -9, z + 13, Blocks.planks, 0, 3);
		world.setBlock(x + 28, y + -9, z + 13, Blocks.bedrock, 0, 3);
		world.setBlock(x + 0, y + -9, z + 14, Blocks.bedrock, 0, 3);
		world.setBlock(x + 1, y + -9, z + 14, Blocks.stone, 0, 3);
		world.setBlock(x + 9, y + -9, z + 14, Blocks.stone, 0, 3);
		world.setBlock(x + 10, y + -9, z + 14, Blocks.planks, 0, 3);
		world.setBlock(x + 27, y + -9, z + 14, Blocks.planks, 0, 3);
		world.setBlock(x + 28, y + -9, z + 14, Blocks.bedrock, 0, 3);
		world.setBlock(x + 0, y + -9, z + 15, Blocks.bedrock, 0, 3);
		world.setBlock(x + 1, y + -9, z + 15, Blocks.stone, 0, 3);
		world.setBlock(x + 9, y + -9, z + 15, Blocks.stone, 0, 3);
		world.setBlock(x + 10, y + -9, z + 15, Blocks.planks, 0, 3);
		world.setBlock(x + 27, y + -9, z + 15, Blocks.planks, 0, 3);
		world.setBlock(x + 28, y + -9, z + 15, Blocks.bedrock, 0, 3);
		world.setBlock(x + 0, y + -9, z + 16, Blocks.bedrock, 0, 3);
		world.setBlock(x + 1, y + -9, z + 16, Blocks.stone, 0, 3);
		world.setBlock(x + 9, y + -9, z + 16, Blocks.stone, 0, 3);
		world.setBlock(x + 10, y + -9, z + 16, Blocks.planks, 0, 3);
		world.setBlock(x + 26, y + -9, z + 16, Blocks.diamond_block, 0, 3);
		world.setBlock(x + 27, y + -9, z + 16, Blocks.planks, 0, 3);
		world.setBlock(x + 28, y + -9, z + 16, Blocks.bedrock, 0, 3);
		world.setBlock(x + 0, y + -9, z + 17, Blocks.bedrock, 0, 3);
		world.setBlock(x + 1, y + -9, z + 17, Blocks.stone, 0, 3);
		world.setBlock(x + 9, y + -9, z + 17, Blocks.stone, 0, 3);
		world.setBlock(x + 10, y + -9, z + 17, Blocks.planks, 0, 3);
		world.setBlock(x + 11, y + -9, z + 17, Blocks.planks, 0, 3);
		world.setBlock(x + 12, y + -9, z + 17, Blocks.planks, 0, 3);
		world.setBlock(x + 13, y + -9, z + 17, Blocks.planks, 0, 3);
		world.setBlock(x + 14, y + -9, z + 17, Blocks.planks, 0, 3);
		world.setBlock(x + 15, y + -9, z + 17, Blocks.planks, 0, 3);
		world.setBlock(x + 16, y + -9, z + 17, Blocks.planks, 0, 3);
		world.setBlock(x + 17, y + -9, z + 17, Blocks.planks, 0, 3);
		world.setBlock(x + 18, y + -9, z + 17, Blocks.planks, 0, 3);
		world.setBlock(x + 19, y + -9, z + 17, Blocks.planks, 0, 3);
		world.setBlock(x + 20, y + -9, z + 17, Blocks.planks, 0, 3);
		world.setBlock(x + 21, y + -9, z + 17, Blocks.planks, 0, 3);
		world.setBlock(x + 22, y + -9, z + 17, Blocks.planks, 0, 3);
		world.setBlock(x + 23, y + -9, z + 17, Blocks.planks, 0, 3);
		world.setBlock(x + 24, y + -9, z + 17, Blocks.planks, 0, 3);
		world.setBlock(x + 25, y + -9, z + 17, Blocks.planks, 0, 3);
		world.setBlock(x + 26, y + -9, z + 17, Blocks.planks, 0, 3);
		world.setBlock(x + 27, y + -9, z + 17, Blocks.planks, 0, 3);
		world.setBlock(x + 28, y + -9, z + 17, Blocks.bedrock, 0, 3);
		world.setBlock(x + 0, y + -9, z + 18, Blocks.bedrock, 0, 3);
		world.setBlock(x + 1, y + -9, z + 18, Blocks.stone, 0, 3);
		world.setBlock(x + 9, y + -9, z + 18, Blocks.stone, 0, 3);
		world.setBlock(x + 10, y + -9, z + 18, Blocks.bedrock, 0, 3);
		world.setBlock(x + 11, y + -9, z + 18, Blocks.bedrock, 0, 3);
		world.setBlock(x + 12, y + -9, z + 18, Blocks.bedrock, 0, 3);
		world.setBlock(x + 13, y + -9, z + 18, Blocks.bedrock, 0, 3);
		world.setBlock(x + 14, y + -9, z + 18, Blocks.bedrock, 0, 3);
		world.setBlock(x + 15, y + -9, z + 18, Blocks.bedrock, 0, 3);
		world.setBlock(x + 16, y + -9, z + 18, Blocks.bedrock, 0, 3);
		world.setBlock(x + 17, y + -9, z + 18, Blocks.bedrock, 0, 3);
		world.setBlock(x + 18, y + -9, z + 18, Blocks.bedrock, 0, 3);
		world.setBlock(x + 19, y + -9, z + 18, Blocks.bedrock, 0, 3);
		world.setBlock(x + 20, y + -9, z + 18, Blocks.bedrock, 0, 3);
		world.setBlock(x + 21, y + -9, z + 18, Blocks.bedrock, 0, 3);
		world.setBlock(x + 22, y + -9, z + 18, Blocks.bedrock, 0, 3);
		world.setBlock(x + 23, y + -9, z + 18, Blocks.bedrock, 0, 3);
		world.setBlock(x + 24, y + -9, z + 18, Blocks.bedrock, 0, 3);
		world.setBlock(x + 25, y + -9, z + 18, Blocks.bedrock, 0, 3);
		world.setBlock(x + 26, y + -9, z + 18, Blocks.bedrock, 0, 3);
		world.setBlock(x + 27, y + -9, z + 18, Blocks.bedrock, 0, 3);
		world.setBlock(x + 28, y + -9, z + 18, Blocks.bedrock, 0, 3);
		world.setBlock(x + 0, y + -9, z + 19, Blocks.bedrock, 0, 3);
		world.setBlock(x + 1, y + -9, z + 19, Blocks.stone, 0, 3);
		world.setBlock(x + 9, y + -9, z + 19, Blocks.stone, 0, 3);
		world.setBlock(x + 10, y + -9, z + 19, Blocks.bedrock, 0, 3);
		world.setBlock(x + 0, y + -9, z + 20, Blocks.bedrock, 0, 3);
		world.setBlock(x + 1, y + -9, z + 20, Blocks.stone, 0, 3);
		world.setBlock(x + 2, y + -9, z + 20, Blocks.stone, 0, 3);
		world.setBlock(x + 3, y + -9, z + 20, Blocks.stone, 0, 3);
		world.setBlock(x + 4, y + -9, z + 20, Blocks.stone, 0, 3);
		world.setBlock(x + 5, y + -9, z + 20, Blocks.iron_door, 8, 3);
		world.setBlock(x + 6, y + -9, z + 20, Blocks.stone, 0, 3);
		world.setBlock(x + 7, y + -9, z + 20, Blocks.stone, 0, 3);
		world.setBlock(x + 8, y + -9, z + 20, Blocks.stone, 0, 3);
		world.setBlock(x + 9, y + -9, z + 20, Blocks.stone, 0, 3);
		world.setBlock(x + 10, y + -9, z + 20, Blocks.bedrock, 0, 3);
		world.setBlock(x + 0, y + -9, z + 21, Blocks.bedrock, 0, 3);
		world.setBlock(x + 1, y + -9, z + 21, Blocks.stone, 0, 3);
		world.setBlock(x + 9, y + -9, z + 21, Blocks.stone, 0, 3);
		world.setBlock(x + 10, y + -9, z + 21, Blocks.bedrock, 0, 3);
		world.setBlock(x + 0, y + -9, z + 22, Blocks.bedrock, 0, 3);
		world.setBlock(x + 1, y + -9, z + 22, Blocks.stone, 0, 3);
		world.setBlock(x + 9, y + -9, z + 22, Blocks.stone, 0, 3);
		world.setBlock(x + 10, y + -9, z + 22, Blocks.bedrock, 0, 3);
		world.setBlock(x + 0, y + -9, z + 23, Blocks.bedrock, 0, 3);
		world.setBlock(x + 1, y + -9, z + 23, Blocks.stone, 0, 3);
		world.setBlock(x + 9, y + -9, z + 23, Blocks.stone, 0, 3);
		world.setBlock(x + 10, y + -9, z + 23, Blocks.bedrock, 0, 3);
		world.setBlock(x + 0, y + -9, z + 24, Blocks.bedrock, 0, 3);
		world.setBlock(x + 1, y + -9, z + 24, Blocks.stone, 0, 3);
		world.setBlock(x + 9, y + -9, z + 24, Blocks.stone, 0, 3);
		world.setBlock(x + 10, y + -9, z + 24, Blocks.bedrock, 0, 3);
		world.setBlock(x + 0, y + -9, z + 25, Blocks.bedrock, 0, 3);
		world.setBlock(x + 1, y + -9, z + 25, Blocks.stone, 0, 3);
		world.setBlock(x + 9, y + -9, z + 25, Blocks.stone, 0, 3);
		world.setBlock(x + 10, y + -9, z + 25, Blocks.bedrock, 0, 3);
		world.setBlock(x + 0, y + -9, z + 26, Blocks.bedrock, 0, 3);
		world.setBlock(x + 1, y + -9, z + 26, Blocks.stone, 0, 3);
		world.setBlock(x + 9, y + -9, z + 26, Blocks.stone, 0, 3);
		world.setBlock(x + 10, y + -9, z + 26, Blocks.bedrock, 0, 3);
		world.setBlock(x + 0, y + -9, z + 27, Blocks.bedrock, 0, 3);
		world.setBlock(x + 1, y + -9, z + 27, Blocks.stone, 0, 3);
		world.setBlock(x + 9, y + -9, z + 27, Blocks.stone, 0, 3);
		world.setBlock(x + 10, y + -9, z + 27, Blocks.bedrock, 0, 3);
		world.setBlock(x + 0, y + -9, z + 28, Blocks.bedrock, 0, 3);
		world.setBlock(x + 1, y + -9, z + 28, Blocks.stone, 0, 3);
		world.setBlock(x + 2, y + -9, z + 28, Blocks.stone, 0, 3);
		world.setBlock(x + 3, y + -9, z + 28, Blocks.stone, 0, 3);
		world.setBlock(x + 4, y + -9, z + 28, Blocks.stone, 0, 3);
		world.setBlock(x + 5, y + -9, z + 28, Blocks.iron_door, 8, 3);
		world.setBlock(x + 6, y + -9, z + 28, Blocks.stone, 0, 3);
		world.setBlock(x + 7, y + -9, z + 28, Blocks.stone, 0, 3);
		world.setBlock(x + 8, y + -9, z + 28, Blocks.stone, 0, 3);
		world.setBlock(x + 9, y + -9, z + 28, Blocks.stone, 0, 3);
		world.setBlock(x + 10, y + -9, z + 28, Blocks.bedrock, 0, 3);
		world.setBlock(x + 0, y + -9, z + 29, Blocks.bedrock, 0, 3);
		world.setBlock(x + 1, y + -9, z + 29, Blocks.stone, 0, 3);
		world.setBlock(x + 9, y + -9, z + 29, Blocks.stone, 0, 3);
		world.setBlock(x + 10, y + -9, z + 29, Blocks.bedrock, 0, 3);
		world.setBlock(x + 0, y + -9, z + 30, Blocks.bedrock, 0, 3);
		world.setBlock(x + 1, y + -9, z + 30, Blocks.stone, 0, 3);
		world.setBlock(x + 9, y + -9, z + 30, Blocks.stone, 0, 3);
		world.setBlock(x + 10, y + -9, z + 30, Blocks.bedrock, 0, 3);
		world.setBlock(x + 0, y + -9, z + 31, Blocks.bedrock, 0, 3);
		world.setBlock(x + 1, y + -9, z + 31, Blocks.stone, 0, 3);
		world.setBlock(x + 9, y + -9, z + 31, Blocks.stone, 0, 3);
		world.setBlock(x + 10, y + -9, z + 31, Blocks.bedrock, 0, 3);
		world.setBlock(x + 0, y + -9, z + 32, Blocks.bedrock, 0, 3);
		world.setBlock(x + 1, y + -9, z + 32, Blocks.stone, 0, 3);
		world.setBlock(x + 9, y + -9, z + 32, Blocks.stone, 0, 3);
		world.setBlock(x + 10, y + -9, z + 32, Blocks.bedrock, 0, 3);
		world.setBlock(x + 0, y + -9, z + 33, Blocks.bedrock, 0, 3);
		world.setBlock(x + 1, y + -9, z + 33, Blocks.stone, 0, 3);
		world.setBlock(x + 9, y + -9, z + 33, Blocks.stone, 0, 3);
		world.setBlock(x + 10, y + -9, z + 33, Blocks.bedrock, 0, 3);
		world.setBlock(x + 0, y + -9, z + 34, Blocks.bedrock, 0, 3);
		world.setBlock(x + 1, y + -9, z + 34, Blocks.stone, 0, 3);
		world.setBlock(x + 9, y + -9, z + 34, Blocks.stone, 0, 3);
		world.setBlock(x + 10, y + -9, z + 34, Blocks.bedrock, 0, 3);
		world.setBlock(x + 0, y + -9, z + 35, Blocks.bedrock, 0, 3);
		world.setBlock(x + 1, y + -9, z + 35, Blocks.stone, 0, 3);
		world.setBlock(x + 9, y + -9, z + 35, Blocks.stone, 0, 3);
		world.setBlock(x + 10, y + -9, z + 35, Blocks.bedrock, 0, 3);
		world.setBlock(x + 0, y + -9, z + 36, Blocks.bedrock, 0, 3);
		world.setBlock(x + 1, y + -9, z + 36, Blocks.stone, 0, 3);
		world.setBlock(x + 2, y + -9, z + 36, Blocks.stone, 0, 3);
		world.setBlock(x + 3, y + -9, z + 36, Blocks.stone, 0, 3);
		world.setBlock(x + 4, y + -9, z + 36, Blocks.stone, 0, 3);
		world.setBlock(x + 5, y + -9, z + 36, Blocks.iron_door, 8, 3);
		world.setBlock(x + 6, y + -9, z + 36, Blocks.stone, 0, 3);
		world.setBlock(x + 7, y + -9, z + 36, Blocks.stone, 0, 3);
		world.setBlock(x + 8, y + -9, z + 36, Blocks.stone, 0, 3);
		world.setBlock(x + 9, y + -9, z + 36, Blocks.stone, 0, 3);
		world.setBlock(x + 10, y + -9, z + 36, Blocks.bedrock, 0, 3);
		world.setBlock(x + 0, y + -9, z + 37, Blocks.bedrock, 0, 3);
		world.setBlock(x + 1, y + -9, z + 37, Blocks.stone, 0, 3);
		world.setBlock(x + 9, y + -9, z + 37, Blocks.stone, 0, 3);
		world.setBlock(x + 10, y + -9, z + 37, Blocks.bedrock, 0, 3);
		world.setBlock(x + 0, y + -9, z + 38, Blocks.bedrock, 0, 3);
		world.setBlock(x + 1, y + -9, z + 38, Blocks.stone, 0, 3);
		world.setBlock(x + 9, y + -9, z + 38, Blocks.stone, 0, 3);
		world.setBlock(x + 10, y + -9, z + 38, Blocks.bedrock, 0, 3);
		world.setBlock(x + 0, y + -9, z + 39, Blocks.bedrock, 0, 3);
		world.setBlock(x + 1, y + -9, z + 39, Blocks.stone, 0, 3);
		world.setBlock(x + 9, y + -9, z + 39, Blocks.stone, 0, 3);
		world.setBlock(x + 10, y + -9, z + 39, Blocks.bedrock, 0, 3);
		world.setBlock(x + 0, y + -9, z + 40, Blocks.bedrock, 0, 3);
		world.setBlock(x + 1, y + -9, z + 40, Blocks.stone, 0, 3);
		world.setBlock(x + 9, y + -9, z + 40, Blocks.stone, 0, 3);
		world.setBlock(x + 10, y + -9, z + 40, Blocks.bedrock, 0, 3);
		world.setBlock(x + 0, y + -9, z + 41, Blocks.bedrock, 0, 3);
		world.setBlock(x + 1, y + -9, z + 41, Blocks.stone, 0, 3);
		world.setBlock(x + 9, y + -9, z + 41, Blocks.stone, 0, 3);
		world.setBlock(x + 10, y + -9, z + 41, Blocks.bedrock, 0, 3);
		world.setBlock(x + 0, y + -9, z + 42, Blocks.bedrock, 0, 3);
		world.setBlock(x + 1, y + -9, z + 42, Blocks.stone, 0, 3);
		world.setBlock(x + 9, y + -9, z + 42, Blocks.stone, 0, 3);
		world.setBlock(x + 10, y + -9, z + 42, Blocks.bedrock, 0, 3);
		world.setBlock(x + 0, y + -9, z + 43, Blocks.bedrock, 0, 3);
		world.setBlock(x + 1, y + -9, z + 43, Blocks.stone, 0, 3);
		world.setBlock(x + 9, y + -9, z + 43, Blocks.stone, 0, 3);
		world.setBlock(x + 10, y + -9, z + 43, Blocks.bedrock, 0, 3);
		world.setBlock(x + 0, y + -9, z + 44, Blocks.bedrock, 0, 3);
		world.setBlock(x + 1, y + -9, z + 44, Blocks.stone, 0, 3);
		world.setBlock(x + 2, y + -9, z + 44, Blocks.stone, 0, 3);
		world.setBlock(x + 3, y + -9, z + 44, Blocks.stone, 0, 3);
		world.setBlock(x + 4, y + -9, z + 44, Blocks.stone, 0, 3);
		world.setBlock(x + 5, y + -9, z + 44, Blocks.iron_door, 8, 3);
		world.setBlock(x + 6, y + -9, z + 44, Blocks.stone, 0, 3);
		world.setBlock(x + 7, y + -9, z + 44, Blocks.stone, 0, 3);
		world.setBlock(x + 8, y + -9, z + 44, Blocks.stone, 0, 3);
		world.setBlock(x + 9, y + -9, z + 44, Blocks.stone, 0, 3);
		world.setBlock(x + 10, y + -9, z + 44, Blocks.bedrock, 0, 3);
		world.setBlock(x + 0, y + -9, z + 45, Blocks.bedrock, 0, 3);
		world.setBlock(x + 1, y + -9, z + 45, Blocks.stone, 0, 3);
		world.setBlock(x + 9, y + -9, z + 45, Blocks.stone, 0, 3);
		world.setBlock(x + 10, y + -9, z + 45, Blocks.bedrock, 0, 3);
		world.setBlock(x + 0, y + -9, z + 46, Blocks.bedrock, 0, 3);
		world.setBlock(x + 1, y + -9, z + 46, Blocks.stone, 0, 3);
		world.setBlock(x + 9, y + -9, z + 46, Blocks.stone, 0, 3);
		world.setBlock(x + 10, y + -9, z + 46, Blocks.bedrock, 0, 3);
		world.setBlock(x + 0, y + -9, z + 47, Blocks.bedrock, 0, 3);
		world.setBlock(x + 1, y + -9, z + 47, Blocks.stone, 0, 3);
		world.setBlock(x + 9, y + -9, z + 47, Blocks.stone, 0, 3);
		world.setBlock(x + 10, y + -9, z + 47, Blocks.bedrock, 0, 3);
		world.setBlock(x + 0, y + -9, z + 48, Blocks.bedrock, 0, 3);
		world.setBlock(x + 1, y + -9, z + 48, Blocks.stone, 0, 3);
		world.setBlock(x + 9, y + -9, z + 48, Blocks.stone, 0, 3);
		world.setBlock(x + 10, y + -9, z + 48, Blocks.bedrock, 0, 3);
		world.setBlock(x + 0, y + -9, z + 49, Blocks.bedrock, 0, 3);
		world.setBlock(x + 1, y + -9, z + 49, Blocks.stone, 0, 3);
		world.setBlock(x + 9, y + -9, z + 49, Blocks.stone, 0, 3);
		world.setBlock(x + 10, y + -9, z + 49, Blocks.bedrock, 0, 3);
		world.setBlock(x + 0, y + -9, z + 50, Blocks.bedrock, 0, 3);
		world.setBlock(x + 1, y + -9, z + 50, Blocks.stone, 0, 3);
		world.setBlock(x + 9, y + -9, z + 50, Blocks.stone, 0, 3);
		world.setBlock(x + 10, y + -9, z + 50, Blocks.bedrock, 0, 3);
		world.setBlock(x + 0, y + -9, z + 51, Blocks.bedrock, 0, 3);
		world.setBlock(x + 1, y + -9, z + 51, Blocks.stone, 0, 3);
		world.setBlock(x + 9, y + -9, z + 51, Blocks.stone, 0, 3);
		world.setBlock(x + 10, y + -9, z + 51, Blocks.bedrock, 0, 3);
		world.setBlock(x + 0, y + -9, z + 52, Blocks.bedrock, 0, 3);
		world.setBlock(x + 1, y + -9, z + 52, Blocks.stone, 0, 3);
		world.setBlock(x + 2, y + -9, z + 52, Blocks.stone, 0, 3);
		world.setBlock(x + 3, y + -9, z + 52, Blocks.stone, 0, 3);
		world.setBlock(x + 4, y + -9, z + 52, Blocks.stone, 0, 3);
		world.setBlock(x + 5, y + -9, z + 52, Blocks.iron_door, 8, 3);
		world.setBlock(x + 6, y + -9, z + 52, Blocks.stone, 0, 3);
		world.setBlock(x + 7, y + -9, z + 52, Blocks.stone, 0, 3);
		world.setBlock(x + 8, y + -9, z + 52, Blocks.stone, 0, 3);
		world.setBlock(x + 9, y + -9, z + 52, Blocks.stone, 0, 3);
		world.setBlock(x + 10, y + -9, z + 52, Blocks.stone, 0, 3);
		world.setBlock(x + 11, y + -9, z + 52, Blocks.stone, 0, 3);
		world.setBlock(x + 12, y + -9, z + 52, Blocks.stone, 0, 3);
		world.setBlock(x + 13, y + -9, z + 52, Blocks.stone, 0, 3);
		world.setBlock(x + 14, y + -9, z + 52, Blocks.stone, 0, 3);
		world.setBlock(x + 15, y + -9, z + 52, Blocks.stone, 0, 3);
		world.setBlock(x + 16, y + -9, z + 52, Blocks.stone, 0, 3);
		world.setBlock(x + 17, y + -9, z + 52, Blocks.stone, 0, 3);
		world.setBlock(x + 0, y + -9, z + 53, Blocks.bedrock, 0, 3);
		world.setBlock(x + 1, y + -9, z + 53, Blocks.stone, 0, 3);
		world.setBlock(x + 9, y + -9, z + 53, Blocks.stone, 0, 3);
		world.setBlock(x + 17, y + -9, z + 53, Blocks.stone, 0, 3);
		world.setBlock(x + 0, y + -9, z + 54, Blocks.bedrock, 0, 3);
		world.setBlock(x + 1, y + -9, z + 54, Blocks.stone, 0, 3);
		world.setBlock(x + 9, y + -9, z + 54, Blocks.stone, 0, 3);
		world.setBlock(x + 17, y + -9, z + 54, Blocks.stone, 0, 3);
		world.setBlock(x + 0, y + -9, z + 55, Blocks.bedrock, 0, 3);
		world.setBlock(x + 1, y + -9, z + 55, Blocks.stone, 0, 3);
		world.setBlock(x + 9, y + -9, z + 55, Blocks.stone, 0, 3);
		world.setBlock(x + 13, y + -9, z + 55, Blocks.stone_stairs, 0, 3);
		world.setBlock(x + 14, y + -9, z + 55, Blocks.stone_slab, 11, 3);
		world.setBlock(x + 17, y + -9, z + 55, Blocks.stone, 0, 3);
		world.setBlock(x + 0, y + -9, z + 56, Blocks.bedrock, 0, 3);
		world.setBlock(x + 1, y + -9, z + 56, Blocks.stone, 0, 3);
		world.setBlock(x + 9, y + -9, z + 56, Blocks.iron_door, 8, 3);
		world.setBlock(x + 13, y + -9, z + 56, Blocks.cobblestone, 0, 3);
		world.setBlock(x + 17, y + -9, z + 56, Blocks.stone, 0, 3);
		world.setBlock(x + 0, y + -9, z + 57, Blocks.bedrock, 0, 3);
		world.setBlock(x + 1, y + -9, z + 57, Blocks.stone, 0, 3);
		world.setBlock(x + 9, y + -9, z + 57, Blocks.stone, 0, 3);
		world.setBlock(x + 17, y + -9, z + 57, Blocks.stone, 0, 3);
		world.setBlock(x + 0, y + -9, z + 58, Blocks.bedrock, 0, 3);
		world.setBlock(x + 1, y + -9, z + 58, Blocks.stone, 0, 3);
		world.setBlock(x + 9, y + -9, z + 58, Blocks.stone, 0, 3);
		world.setBlock(x + 17, y + -9, z + 58, Blocks.stone, 0, 3);
		world.setBlock(x + 0, y + -9, z + 59, Blocks.bedrock, 0, 3);
		world.setBlock(x + 1, y + -9, z + 59, Blocks.stone, 0, 3);
		world.setBlock(x + 9, y + -9, z + 59, Blocks.stone, 0, 3);
		world.setBlock(x + 17, y + -9, z + 59, Blocks.stone, 0, 3);
		world.setBlock(x + 0, y + -9, z + 60, Blocks.bedrock, 0, 3);
		world.setBlock(x + 1, y + -9, z + 60, Blocks.stone, 0, 3);
		world.setBlock(x + 2, y + -9, z + 60, Blocks.stone, 0, 3);
		world.setBlock(x + 3, y + -9, z + 60, Blocks.stone, 0, 3);
		world.setBlock(x + 4, y + -9, z + 60, Blocks.stone, 0, 3);
		world.setBlock(x + 5, y + -9, z + 60, Blocks.stone, 0, 3);
		world.setBlock(x + 6, y + -9, z + 60, Blocks.stone, 0, 3);
		world.setBlock(x + 7, y + -9, z + 60, Blocks.stone, 0, 3);
		world.setBlock(x + 8, y + -9, z + 60, Blocks.stone, 0, 3);
		world.setBlock(x + 9, y + -9, z + 60, Blocks.stone, 0, 3);
		world.setBlock(x + 10, y + -9, z + 60, Blocks.stone, 0, 3);
		world.setBlock(x + 11, y + -9, z + 60, Blocks.stone, 0, 3);
		world.setBlock(x + 12, y + -9, z + 60, Blocks.stone, 0, 3);
		world.setBlock(x + 13, y + -9, z + 60, Blocks.stone, 0, 3);
		world.setBlock(x + 14, y + -9, z + 60, Blocks.stone, 0, 3);
		world.setBlock(x + 15, y + -9, z + 60, Blocks.stone, 0, 3);
		world.setBlock(x + 16, y + -9, z + 60, Blocks.stone, 0, 3);
		world.setBlock(x + 17, y + -9, z + 60, Blocks.stone, 0, 3);
		world.setBlock(x + 0, y + -9, z + 61, Blocks.bedrock, 0, 3);
		world.setBlock(x + 1, y + -9, z + 61, Blocks.bedrock, 0, 3);
		world.setBlock(x + 2, y + -9, z + 61, Blocks.bedrock, 0, 3);
		world.setBlock(x + 3, y + -9, z + 61, Blocks.bedrock, 0, 3);
		world.setBlock(x + 4, y + -9, z + 61, Blocks.bedrock, 0, 3);
		world.setBlock(x + 5, y + -9, z + 61, Blocks.bedrock, 0, 3);
		world.setBlock(x + 6, y + -9, z + 61, Blocks.bedrock, 0, 3);
		world.setBlock(x + 7, y + -9, z + 61, Blocks.bedrock, 0, 3);
		world.setBlock(x + 8, y + -9, z + 61, Blocks.bedrock, 0, 3);
		world.setBlock(x + 9, y + -9, z + 61, Blocks.bedrock, 0, 3);
		world.setBlock(x + 0, y + -8, z + 3, Blocks.bedrock, 0, 3);
		world.setBlock(x + 1, y + -8, z + 3, Blocks.bedrock, 0, 3);
		world.setBlock(x + 2, y + -8, z + 3, Blocks.bedrock, 0, 3);
		world.setBlock(x + 3, y + -8, z + 3, Blocks.bedrock, 0, 3);
		world.setBlock(x + 4, y + -8, z + 3, Blocks.bedrock, 0, 3);
		world.setBlock(x + 5, y + -8, z + 3, Blocks.bedrock, 0, 3);
		world.setBlock(x + 6, y + -8, z + 3, Blocks.bedrock, 0, 3);
		world.setBlock(x + 7, y + -8, z + 3, Blocks.bedrock, 0, 3);
		world.setBlock(x + 8, y + -8, z + 3, Blocks.bedrock, 0, 3);
		world.setBlock(x + 9, y + -8, z + 3, Blocks.bedrock, 0, 3);
		world.setBlock(x + 10, y + -8, z + 3, Blocks.bedrock, 0, 3);
		world.setBlock(x + 11, y + -8, z + 3, Blocks.bedrock, 0, 3);
		world.setBlock(x + 12, y + -8, z + 3, Blocks.bedrock, 0, 3);
		world.setBlock(x + 13, y + -8, z + 3, Blocks.bedrock, 0, 3);
		world.setBlock(x + 14, y + -8, z + 3, Blocks.bedrock, 0, 3);
		world.setBlock(x + 15, y + -8, z + 3, Blocks.bedrock, 0, 3);
		world.setBlock(x + 16, y + -8, z + 3, Blocks.bedrock, 0, 3);
		world.setBlock(x + 17, y + -8, z + 3, Blocks.bedrock, 0, 3);
		world.setBlock(x + 18, y + -8, z + 3, Blocks.bedrock, 0, 3);
		world.setBlock(x + 19, y + -8, z + 3, Blocks.bedrock, 0, 3);
		world.setBlock(x + 20, y + -8, z + 3, Blocks.bedrock, 0, 3);
		world.setBlock(x + 21, y + -8, z + 3, Blocks.bedrock, 0, 3);
		world.setBlock(x + 22, y + -8, z + 3, Blocks.bedrock, 0, 3);
		world.setBlock(x + 23, y + -8, z + 3, Blocks.bedrock, 0, 3);
		world.setBlock(x + 24, y + -8, z + 3, Blocks.bedrock, 0, 3);
		world.setBlock(x + 25, y + -8, z + 3, Blocks.bedrock, 0, 3);
		world.setBlock(x + 26, y + -8, z + 3, Blocks.bedrock, 0, 3);
		world.setBlock(x + 27, y + -8, z + 3, Blocks.bedrock, 0, 3);
		world.setBlock(x + 28, y + -8, z + 3, Blocks.bedrock, 0, 3);
		world.setBlock(x + 0, y + -8, z + 4, Blocks.bedrock, 0, 3);
		world.setBlock(x + 1, y + -8, z + 4, Blocks.stone, 0, 3);
		world.setBlock(x + 2, y + -8, z + 4, Blocks.stone, 0, 3);
		world.setBlock(x + 3, y + -8, z + 4, Blocks.stone, 0, 3);
		world.setBlock(x + 4, y + -8, z + 4, Blocks.stone, 0, 3);
		world.setBlock(x + 5, y + -8, z + 4, Blocks.stone, 0, 3);
		world.setBlock(x + 6, y + -8, z + 4, Blocks.stone, 0, 3);
		world.setBlock(x + 7, y + -8, z + 4, Blocks.stone, 0, 3);
		world.setBlock(x + 8, y + -8, z + 4, Blocks.stone, 0, 3);
		world.setBlock(x + 9, y + -8, z + 4, Blocks.stone, 0, 3);
		world.setBlock(x + 10, y + -8, z + 4, Blocks.planks, 0, 3);
		world.setBlock(x + 11, y + -8, z + 4, Blocks.planks, 0, 3);
		world.setBlock(x + 12, y + -8, z + 4, Blocks.planks, 0, 3);
		world.setBlock(x + 13, y + -8, z + 4, Blocks.planks, 0, 3);
		world.setBlock(x + 14, y + -8, z + 4, Blocks.planks, 0, 3);
		world.setBlock(x + 15, y + -8, z + 4, Blocks.planks, 0, 3);
		world.setBlock(x + 16, y + -8, z + 4, Blocks.planks, 0, 3);
		world.setBlock(x + 17, y + -8, z + 4, Blocks.planks, 0, 3);
		world.setBlock(x + 18, y + -8, z + 4, Blocks.planks, 0, 3);
		world.setBlock(x + 19, y + -8, z + 4, Blocks.planks, 0, 3);
		world.setBlock(x + 20, y + -8, z + 4, Blocks.planks, 0, 3);
		world.setBlock(x + 21, y + -8, z + 4, Blocks.planks, 0, 3);
		world.setBlock(x + 22, y + -8, z + 4, Blocks.planks, 0, 3);
		world.setBlock(x + 23, y + -8, z + 4, Blocks.planks, 0, 3);
		world.setBlock(x + 24, y + -8, z + 4, Blocks.planks, 0, 3);
		world.setBlock(x + 25, y + -8, z + 4, Blocks.planks, 0, 3);
		world.setBlock(x + 26, y + -8, z + 4, Blocks.planks, 0, 3);
		world.setBlock(x + 27, y + -8, z + 4, Blocks.planks, 0, 3);
		world.setBlock(x + 28, y + -8, z + 4, Blocks.bedrock, 0, 3);
		world.setBlock(x + 0, y + -8, z + 5, Blocks.bedrock, 0, 3);
		world.setBlock(x + 1, y + -8, z + 5, Blocks.stone, 0, 3);
		world.setBlock(x + 9, y + -8, z + 5, Blocks.stone, 0, 3);
		world.setBlock(x + 10, y + -8, z + 5, Blocks.planks, 0, 3);
		world.setBlock(x + 26, y + -8, z + 5, Blocks.gold_block, 0, 3);
		world.setBlock(x + 27, y + -8, z + 5, Blocks.planks, 0, 3);
		world.setBlock(x + 28, y + -8, z + 5, Blocks.bedrock, 0, 3);
		world.setBlock(x + 0, y + -8, z + 6, Blocks.bedrock, 0, 3);
		world.setBlock(x + 1, y + -8, z + 6, Blocks.stone, 0, 3);
		world.setBlock(x + 9, y + -8, z + 6, Blocks.stone, 0, 3);
		world.setBlock(x + 10, y + -8, z + 6, Blocks.planks, 0, 3);
		world.setBlock(x + 27, y + -8, z + 6, Blocks.planks, 0, 3);
		world.setBlock(x + 28, y + -8, z + 6, Blocks.bedrock, 0, 3);
		world.setBlock(x + 0, y + -8, z + 7, Blocks.bedrock, 0, 3);
		world.setBlock(x + 1, y + -8, z + 7, Blocks.stone, 0, 3);
		world.setBlock(x + 9, y + -8, z + 7, Blocks.stone, 0, 3);
		world.setBlock(x + 10, y + -8, z + 7, Blocks.planks, 0, 3);
		world.setBlock(x + 27, y + -8, z + 7, Blocks.planks, 0, 3);
		world.setBlock(x + 28, y + -8, z + 7, Blocks.bedrock, 0, 3);
		world.setBlock(x + 0, y + -8, z + 8, Blocks.bedrock, 0, 3);
		world.setBlock(x + 1, y + -8, z + 8, Blocks.stone, 0, 3);
		world.setBlock(x + 9, y + -8, z + 8, Blocks.stone, 0, 3);
		world.setBlock(x + 10, y + -8, z + 8, Blocks.planks, 0, 3);
		world.setBlock(x + 27, y + -8, z + 8, Blocks.planks, 0, 3);
		world.setBlock(x + 28, y + -8, z + 8, Blocks.bedrock, 0, 3);
		world.setBlock(x + 0, y + -8, z + 9, Blocks.bedrock, 0, 3);
		world.setBlock(x + 1, y + -8, z + 9, Blocks.stone, 0, 3);
		world.setBlock(x + 9, y + -8, z + 9, Blocks.stone, 0, 3);
		world.setBlock(x + 10, y + -8, z + 9, Blocks.planks, 0, 3);
		world.setBlock(x + 27, y + -8, z + 9, Blocks.planks, 0, 3);
		world.setBlock(x + 28, y + -8, z + 9, Blocks.bedrock, 0, 3);
		world.setBlock(x + 0, y + -8, z + 10, Blocks.bedrock, 0, 3);
		world.setBlock(x + 1, y + -8, z + 10, Blocks.stone, 0, 3);
		world.setBlock(x + 9, y + -8, z + 10, Blocks.stone, 0, 3);
		world.setBlock(x + 10, y + -8, z + 10, Blocks.planks, 0, 3);
		world.setBlock(x + 27, y + -8, z + 10, Blocks.planks, 0, 3);
		world.setBlock(x + 28, y + -8, z + 10, Blocks.bedrock, 0, 3);
		world.setBlock(x + 0, y + -8, z + 11, Blocks.bedrock, 0, 3);
		world.setBlock(x + 1, y + -8, z + 11, Blocks.stone, 0, 3);
		world.setBlock(x + 9, y + -8, z + 11, Blocks.stone, 0, 3);
		world.setBlock(x + 10, y + -8, z + 11, Blocks.planks, 0, 3);
		world.setBlock(x + 19, y + -8, z + 11, Blocks.iron_block, 0, 3);
		world.setBlock(x + 27, y + -8, z + 11, Blocks.planks, 0, 3);
		world.setBlock(x + 28, y + -8, z + 11, Blocks.bedrock, 0, 3);
		world.setBlock(x + 0, y + -8, z + 12, Blocks.bedrock, 0, 3);
		world.setBlock(x + 1, y + -8, z + 12, Blocks.stone, 0, 3);
		world.setBlock(x + 2, y + -8, z + 12, Blocks.stone, 0, 3);
		world.setBlock(x + 3, y + -8, z + 12, Blocks.stone, 0, 3);
		world.setBlock(x + 4, y + -8, z + 12, Blocks.stone, 0, 3);
		world.setBlock(x + 5, y + -8, z + 12, Blocks.stone, 0, 3);
		world.setBlock(x + 6, y + -8, z + 12, Blocks.stone, 0, 3);
		world.setBlock(x + 7, y + -8, z + 12, Blocks.stone, 0, 3);
		world.setBlock(x + 8, y + -8, z + 12, Blocks.stone, 0, 3);
		world.setBlock(x + 9, y + -8, z + 12, Blocks.stone, 0, 3);
		world.setBlock(x + 10, y + -8, z + 12, Blocks.planks, 0, 3);
		world.setBlock(x + 27, y + -8, z + 12, Blocks.planks, 0, 3);
		world.setBlock(x + 28, y + -8, z + 12, Blocks.bedrock, 0, 3);
		world.setBlock(x + 0, y + -8, z + 13, Blocks.bedrock, 0, 3);
		world.setBlock(x + 1, y + -8, z + 13, Blocks.stone, 0, 3);
		world.setBlock(x + 9, y + -8, z + 13, Blocks.stone, 0, 3);
		world.setBlock(x + 10, y + -8, z + 13, Blocks.planks, 0, 3);
		world.setBlock(x + 27, y + -8, z + 13, Blocks.planks, 0, 3);
		world.setBlock(x + 28, y + -8, z + 13, Blocks.bedrock, 0, 3);
		world.setBlock(x + 0, y + -8, z + 14, Blocks.bedrock, 0, 3);
		world.setBlock(x + 1, y + -8, z + 14, Blocks.stone, 0, 3);
		world.setBlock(x + 9, y + -8, z + 14, Blocks.stone, 0, 3);
		world.setBlock(x + 10, y + -8, z + 14, Blocks.planks, 0, 3);
		world.setBlock(x + 27, y + -8, z + 14, Blocks.planks, 0, 3);
		world.setBlock(x + 28, y + -8, z + 14, Blocks.bedrock, 0, 3);
		world.setBlock(x + 0, y + -8, z + 15, Blocks.bedrock, 0, 3);
		world.setBlock(x + 1, y + -8, z + 15, Blocks.stone, 0, 3);
		world.setBlock(x + 9, y + -8, z + 15, Blocks.stone, 0, 3);
		world.setBlock(x + 10, y + -8, z + 15, Blocks.planks, 0, 3);
		world.setBlock(x + 27, y + -8, z + 15, Blocks.planks, 0, 3);
		world.setBlock(x + 28, y + -8, z + 15, Blocks.bedrock, 0, 3);
		world.setBlock(x + 0, y + -8, z + 16, Blocks.bedrock, 0, 3);
		world.setBlock(x + 1, y + -8, z + 16, Blocks.stone, 0, 3);
		world.setBlock(x + 9, y + -8, z + 16, Blocks.stone, 0, 3);
		world.setBlock(x + 10, y + -8, z + 16, Blocks.planks, 0, 3);
		world.setBlock(x + 27, y + -8, z + 16, Blocks.planks, 0, 3);
		world.setBlock(x + 28, y + -8, z + 16, Blocks.bedrock, 0, 3);
		world.setBlock(x + 0, y + -8, z + 17, Blocks.bedrock, 0, 3);
		world.setBlock(x + 1, y + -8, z + 17, Blocks.stone, 0, 3);
		world.setBlock(x + 9, y + -8, z + 17, Blocks.stone, 0, 3);
		world.setBlock(x + 10, y + -8, z + 17, Blocks.planks, 0, 3);
		world.setBlock(x + 11, y + -8, z + 17, Blocks.planks, 0, 3);
		world.setBlock(x + 12, y + -8, z + 17, Blocks.planks, 0, 3);
		world.setBlock(x + 13, y + -8, z + 17, Blocks.planks, 0, 3);
		world.setBlock(x + 14, y + -8, z + 17, Blocks.planks, 0, 3);
		world.setBlock(x + 15, y + -8, z + 17, Blocks.planks, 0, 3);
		world.setBlock(x + 16, y + -8, z + 17, Blocks.planks, 0, 3);
		world.setBlock(x + 17, y + -8, z + 17, Blocks.planks, 0, 3);
		world.setBlock(x + 18, y + -8, z + 17, Blocks.planks, 0, 3);
		world.setBlock(x + 19, y + -8, z + 17, Blocks.planks, 0, 3);
		world.setBlock(x + 20, y + -8, z + 17, Blocks.planks, 0, 3);
		world.setBlock(x + 21, y + -8, z + 17, Blocks.planks, 0, 3);
		world.setBlock(x + 22, y + -8, z + 17, Blocks.planks, 0, 3);
		world.setBlock(x + 23, y + -8, z + 17, Blocks.planks, 0, 3);
		world.setBlock(x + 24, y + -8, z + 17, Blocks.planks, 0, 3);
		world.setBlock(x + 25, y + -8, z + 17, Blocks.planks, 0, 3);
		world.setBlock(x + 26, y + -8, z + 17, Blocks.planks, 0, 3);
		world.setBlock(x + 27, y + -8, z + 17, Blocks.planks, 0, 3);
		world.setBlock(x + 28, y + -8, z + 17, Blocks.bedrock, 0, 3);
		world.setBlock(x + 0, y + -8, z + 18, Blocks.bedrock, 0, 3);
		world.setBlock(x + 1, y + -8, z + 18, Blocks.stone, 0, 3);
		world.setBlock(x + 9, y + -8, z + 18, Blocks.stone, 0, 3);
		world.setBlock(x + 10, y + -8, z + 18, Blocks.bedrock, 0, 3);
		world.setBlock(x + 11, y + -8, z + 18, Blocks.bedrock, 0, 3);
		world.setBlock(x + 12, y + -8, z + 18, Blocks.bedrock, 0, 3);
		world.setBlock(x + 13, y + -8, z + 18, Blocks.bedrock, 0, 3);
		world.setBlock(x + 14, y + -8, z + 18, Blocks.bedrock, 0, 3);
		world.setBlock(x + 15, y + -8, z + 18, Blocks.bedrock, 0, 3);
		world.setBlock(x + 16, y + -8, z + 18, Blocks.bedrock, 0, 3);
		world.setBlock(x + 17, y + -8, z + 18, Blocks.bedrock, 0, 3);
		world.setBlock(x + 18, y + -8, z + 18, Blocks.bedrock, 0, 3);
		world.setBlock(x + 19, y + -8, z + 18, Blocks.bedrock, 0, 3);
		world.setBlock(x + 20, y + -8, z + 18, Blocks.bedrock, 0, 3);
		world.setBlock(x + 21, y + -8, z + 18, Blocks.bedrock, 0, 3);
		world.setBlock(x + 22, y + -8, z + 18, Blocks.bedrock, 0, 3);
		world.setBlock(x + 23, y + -8, z + 18, Blocks.bedrock, 0, 3);
		world.setBlock(x + 24, y + -8, z + 18, Blocks.bedrock, 0, 3);
		world.setBlock(x + 25, y + -8, z + 18, Blocks.bedrock, 0, 3);
		world.setBlock(x + 26, y + -8, z + 18, Blocks.bedrock, 0, 3);
		world.setBlock(x + 27, y + -8, z + 18, Blocks.bedrock, 0, 3);
		world.setBlock(x + 28, y + -8, z + 18, Blocks.bedrock, 0, 3);
		world.setBlock(x + 0, y + -8, z + 19, Blocks.bedrock, 0, 3);
		world.setBlock(x + 1, y + -8, z + 19, Blocks.stone, 0, 3);
		world.setBlock(x + 9, y + -8, z + 19, Blocks.stone, 0, 3);
		world.setBlock(x + 10, y + -8, z + 19, Blocks.bedrock, 0, 3);
		world.setBlock(x + 0, y + -8, z + 20, Blocks.bedrock, 0, 3);
		world.setBlock(x + 1, y + -8, z + 20, Blocks.stone, 0, 3);
		world.setBlock(x + 2, y + -8, z + 20, Blocks.stone, 0, 3);
		world.setBlock(x + 3, y + -8, z + 20, Blocks.stone, 0, 3);
		world.setBlock(x + 4, y + -8, z + 20, Blocks.stone, 0, 3);
		world.setBlock(x + 5, y + -8, z + 20, Blocks.stone, 0, 3);
		world.setBlock(x + 6, y + -8, z + 20, Blocks.stone, 0, 3);
		world.setBlock(x + 7, y + -8, z + 20, Blocks.stone, 0, 3);
		world.setBlock(x + 8, y + -8, z + 20, Blocks.stone, 0, 3);
		world.setBlock(x + 9, y + -8, z + 20, Blocks.stone, 0, 3);
		world.setBlock(x + 10, y + -8, z + 20, Blocks.bedrock, 0, 3);
		world.setBlock(x + 0, y + -8, z + 21, Blocks.bedrock, 0, 3);
		world.setBlock(x + 1, y + -8, z + 21, Blocks.stone, 0, 3);
		world.setBlock(x + 9, y + -8, z + 21, Blocks.stone, 0, 3);
		world.setBlock(x + 10, y + -8, z + 21, Blocks.bedrock, 0, 3);
		world.setBlock(x + 0, y + -8, z + 22, Blocks.bedrock, 0, 3);
		world.setBlock(x + 1, y + -8, z + 22, Blocks.stone, 0, 3);
		world.setBlock(x + 9, y + -8, z + 22, Blocks.stone, 0, 3);
		world.setBlock(x + 10, y + -8, z + 22, Blocks.bedrock, 0, 3);
		world.setBlock(x + 0, y + -8, z + 23, Blocks.bedrock, 0, 3);
		world.setBlock(x + 1, y + -8, z + 23, Blocks.stone, 0, 3);
		world.setBlock(x + 9, y + -8, z + 23, Blocks.stone, 0, 3);
		world.setBlock(x + 10, y + -8, z + 23, Blocks.bedrock, 0, 3);
		world.setBlock(x + 0, y + -8, z + 24, Blocks.bedrock, 0, 3);
		world.setBlock(x + 1, y + -8, z + 24, Blocks.stone, 0, 3);
		world.setBlock(x + 9, y + -8, z + 24, Blocks.stone, 0, 3);
		world.setBlock(x + 10, y + -8, z + 24, Blocks.bedrock, 0, 3);
		world.setBlock(x + 0, y + -8, z + 25, Blocks.bedrock, 0, 3);
		world.setBlock(x + 1, y + -8, z + 25, Blocks.stone, 0, 3);
		world.setBlock(x + 9, y + -8, z + 25, Blocks.stone, 0, 3);
		world.setBlock(x + 10, y + -8, z + 25, Blocks.bedrock, 0, 3);
		world.setBlock(x + 0, y + -8, z + 26, Blocks.bedrock, 0, 3);
		world.setBlock(x + 1, y + -8, z + 26, Blocks.stone, 0, 3);
		world.setBlock(x + 9, y + -8, z + 26, Blocks.stone, 0, 3);
		world.setBlock(x + 10, y + -8, z + 26, Blocks.bedrock, 0, 3);
		world.setBlock(x + 0, y + -8, z + 27, Blocks.bedrock, 0, 3);
		world.setBlock(x + 1, y + -8, z + 27, Blocks.stone, 0, 3);
		world.setBlock(x + 9, y + -8, z + 27, Blocks.stone, 0, 3);
		world.setBlock(x + 10, y + -8, z + 27, Blocks.bedrock, 0, 3);
		world.setBlock(x + 0, y + -8, z + 28, Blocks.bedrock, 0, 3);
		world.setBlock(x + 1, y + -8, z + 28, Blocks.stone, 0, 3);
		world.setBlock(x + 2, y + -8, z + 28, Blocks.stone, 0, 3);
		world.setBlock(x + 3, y + -8, z + 28, Blocks.stone, 0, 3);
		world.setBlock(x + 4, y + -8, z + 28, Blocks.stone, 0, 3);
		world.setBlock(x + 5, y + -8, z + 28, Blocks.stone, 0, 3);
		world.setBlock(x + 6, y + -8, z + 28, Blocks.stone, 0, 3);
		world.setBlock(x + 7, y + -8, z + 28, Blocks.stone, 0, 3);
		world.setBlock(x + 8, y + -8, z + 28, Blocks.stone, 0, 3);
		world.setBlock(x + 9, y + -8, z + 28, Blocks.stone, 0, 3);
		world.setBlock(x + 10, y + -8, z + 28, Blocks.bedrock, 0, 3);
		world.setBlock(x + 0, y + -8, z + 29, Blocks.bedrock, 0, 3);
		world.setBlock(x + 1, y + -8, z + 29, Blocks.stone, 0, 3);
		world.setBlock(x + 9, y + -8, z + 29, Blocks.stone, 0, 3);
		world.setBlock(x + 10, y + -8, z + 29, Blocks.bedrock, 0, 3);
		world.setBlock(x + 0, y + -8, z + 30, Blocks.bedrock, 0, 3);
		world.setBlock(x + 1, y + -8, z + 30, Blocks.stone, 0, 3);
		world.setBlock(x + 9, y + -8, z + 30, Blocks.stone, 0, 3);
		world.setBlock(x + 10, y + -8, z + 30, Blocks.bedrock, 0, 3);
		world.setBlock(x + 0, y + -8, z + 31, Blocks.bedrock, 0, 3);
		world.setBlock(x + 1, y + -8, z + 31, Blocks.stone, 0, 3);
		world.setBlock(x + 9, y + -8, z + 31, Blocks.stone, 0, 3);
		world.setBlock(x + 10, y + -8, z + 31, Blocks.bedrock, 0, 3);
		world.setBlock(x + 0, y + -8, z + 32, Blocks.bedrock, 0, 3);
		world.setBlock(x + 1, y + -8, z + 32, Blocks.stone, 0, 3);
		world.setBlock(x + 9, y + -8, z + 32, Blocks.stone, 0, 3);
		world.setBlock(x + 10, y + -8, z + 32, Blocks.bedrock, 0, 3);
		world.setBlock(x + 0, y + -8, z + 33, Blocks.bedrock, 0, 3);
		world.setBlock(x + 1, y + -8, z + 33, Blocks.stone, 0, 3);
		world.setBlock(x + 9, y + -8, z + 33, Blocks.stone, 0, 3);
		world.setBlock(x + 10, y + -8, z + 33, Blocks.bedrock, 0, 3);
		world.setBlock(x + 0, y + -8, z + 34, Blocks.bedrock, 0, 3);
		world.setBlock(x + 1, y + -8, z + 34, Blocks.stone, 0, 3);
		world.setBlock(x + 9, y + -8, z + 34, Blocks.stone, 0, 3);
		world.setBlock(x + 10, y + -8, z + 34, Blocks.bedrock, 0, 3);
		world.setBlock(x + 0, y + -8, z + 35, Blocks.bedrock, 0, 3);
		world.setBlock(x + 1, y + -8, z + 35, Blocks.stone, 0, 3);
		world.setBlock(x + 9, y + -8, z + 35, Blocks.stone, 0, 3);
		world.setBlock(x + 10, y + -8, z + 35, Blocks.bedrock, 0, 3);
		world.setBlock(x + 0, y + -8, z + 36, Blocks.bedrock, 0, 3);
		world.setBlock(x + 1, y + -8, z + 36, Blocks.stone, 0, 3);
		world.setBlock(x + 2, y + -8, z + 36, Blocks.stone, 0, 3);
		world.setBlock(x + 3, y + -8, z + 36, Blocks.stone, 0, 3);
		world.setBlock(x + 4, y + -8, z + 36, Blocks.stone, 0, 3);
		world.setBlock(x + 5, y + -8, z + 36, Blocks.stone, 0, 3);
		world.setBlock(x + 6, y + -8, z + 36, Blocks.stone, 0, 3);
		world.setBlock(x + 7, y + -8, z + 36, Blocks.stone, 0, 3);
		world.setBlock(x + 8, y + -8, z + 36, Blocks.stone, 0, 3);
		world.setBlock(x + 9, y + -8, z + 36, Blocks.stone, 0, 3);
		world.setBlock(x + 10, y + -8, z + 36, Blocks.bedrock, 0, 3);
		world.setBlock(x + 0, y + -8, z + 37, Blocks.bedrock, 0, 3);
		world.setBlock(x + 1, y + -8, z + 37, Blocks.stone, 0, 3);
		world.setBlock(x + 9, y + -8, z + 37, Blocks.stone, 0, 3);
		world.setBlock(x + 10, y + -8, z + 37, Blocks.bedrock, 0, 3);
		world.setBlock(x + 0, y + -8, z + 38, Blocks.bedrock, 0, 3);
		world.setBlock(x + 1, y + -8, z + 38, Blocks.stone, 0, 3);
		world.setBlock(x + 9, y + -8, z + 38, Blocks.stone, 0, 3);
		world.setBlock(x + 10, y + -8, z + 38, Blocks.bedrock, 0, 3);
		world.setBlock(x + 0, y + -8, z + 39, Blocks.bedrock, 0, 3);
		world.setBlock(x + 1, y + -8, z + 39, Blocks.stone, 0, 3);
		world.setBlock(x + 9, y + -8, z + 39, Blocks.stone, 0, 3);
		world.setBlock(x + 10, y + -8, z + 39, Blocks.bedrock, 0, 3);
		world.setBlock(x + 0, y + -8, z + 40, Blocks.bedrock, 0, 3);
		world.setBlock(x + 1, y + -8, z + 40, Blocks.stone, 0, 3);
		world.setBlock(x + 9, y + -8, z + 40, Blocks.stone, 0, 3);
		world.setBlock(x + 10, y + -8, z + 40, Blocks.bedrock, 0, 3);
		world.setBlock(x + 0, y + -8, z + 41, Blocks.bedrock, 0, 3);
		world.setBlock(x + 1, y + -8, z + 41, Blocks.stone, 0, 3);
		world.setBlock(x + 9, y + -8, z + 41, Blocks.stone, 0, 3);
		world.setBlock(x + 10, y + -8, z + 41, Blocks.bedrock, 0, 3);
		world.setBlock(x + 0, y + -8, z + 42, Blocks.bedrock, 0, 3);
		world.setBlock(x + 1, y + -8, z + 42, Blocks.stone, 0, 3);
		world.setBlock(x + 9, y + -8, z + 42, Blocks.stone, 0, 3);
		world.setBlock(x + 10, y + -8, z + 42, Blocks.bedrock, 0, 3);
		world.setBlock(x + 0, y + -8, z + 43, Blocks.bedrock, 0, 3);
		world.setBlock(x + 1, y + -8, z + 43, Blocks.stone, 0, 3);
		world.setBlock(x + 9, y + -8, z + 43, Blocks.stone, 0, 3);
		world.setBlock(x + 10, y + -8, z + 43, Blocks.bedrock, 0, 3);
		world.setBlock(x + 0, y + -8, z + 44, Blocks.bedrock, 0, 3);
		world.setBlock(x + 1, y + -8, z + 44, Blocks.stone, 0, 3);
		world.setBlock(x + 2, y + -8, z + 44, Blocks.stone, 0, 3);
		world.setBlock(x + 3, y + -8, z + 44, Blocks.stone, 0, 3);
		world.setBlock(x + 4, y + -8, z + 44, Blocks.stone, 0, 3);
		world.setBlock(x + 5, y + -8, z + 44, Blocks.stone, 0, 3);
		world.setBlock(x + 6, y + -8, z + 44, Blocks.stone, 0, 3);
		world.setBlock(x + 7, y + -8, z + 44, Blocks.stone, 0, 3);
		world.setBlock(x + 8, y + -8, z + 44, Blocks.stone, 0, 3);
		world.setBlock(x + 9, y + -8, z + 44, Blocks.stone, 0, 3);
		world.setBlock(x + 10, y + -8, z + 44, Blocks.bedrock, 0, 3);
		world.setBlock(x + 0, y + -8, z + 45, Blocks.bedrock, 0, 3);
		world.setBlock(x + 1, y + -8, z + 45, Blocks.stone, 0, 3);
		world.setBlock(x + 9, y + -8, z + 45, Blocks.stone, 0, 3);
		world.setBlock(x + 10, y + -8, z + 45, Blocks.bedrock, 0, 3);
		world.setBlock(x + 0, y + -8, z + 46, Blocks.bedrock, 0, 3);
		world.setBlock(x + 1, y + -8, z + 46, Blocks.stone, 0, 3);
		world.setBlock(x + 9, y + -8, z + 46, Blocks.stone, 0, 3);
		world.setBlock(x + 10, y + -8, z + 46, Blocks.bedrock, 0, 3);
		world.setBlock(x + 0, y + -8, z + 47, Blocks.bedrock, 0, 3);
		world.setBlock(x + 1, y + -8, z + 47, Blocks.stone, 0, 3);
		world.setBlock(x + 9, y + -8, z + 47, Blocks.stone, 0, 3);
		world.setBlock(x + 10, y + -8, z + 47, Blocks.bedrock, 0, 3);
		world.setBlock(x + 0, y + -8, z + 48, Blocks.bedrock, 0, 3);
		world.setBlock(x + 1, y + -8, z + 48, Blocks.stone, 0, 3);
		world.setBlock(x + 9, y + -8, z + 48, Blocks.stone, 0, 3);
		world.setBlock(x + 10, y + -8, z + 48, Blocks.bedrock, 0, 3);
		world.setBlock(x + 0, y + -8, z + 49, Blocks.bedrock, 0, 3);
		world.setBlock(x + 1, y + -8, z + 49, Blocks.stone, 0, 3);
		world.setBlock(x + 9, y + -8, z + 49, Blocks.stone, 0, 3);
		world.setBlock(x + 10, y + -8, z + 49, Blocks.bedrock, 0, 3);
		world.setBlock(x + 0, y + -8, z + 50, Blocks.bedrock, 0, 3);
		world.setBlock(x + 1, y + -8, z + 50, Blocks.stone, 0, 3);
		world.setBlock(x + 9, y + -8, z + 50, Blocks.stone, 0, 3);
		world.setBlock(x + 10, y + -8, z + 50, Blocks.bedrock, 0, 3);
		world.setBlock(x + 0, y + -8, z + 51, Blocks.bedrock, 0, 3);
		world.setBlock(x + 1, y + -8, z + 51, Blocks.stone, 0, 3);
		world.setBlock(x + 9, y + -8, z + 51, Blocks.stone, 0, 3);
		world.setBlock(x + 10, y + -8, z + 51, Blocks.bedrock, 0, 3);
		world.setBlock(x + 0, y + -8, z + 52, Blocks.bedrock, 0, 3);
		world.setBlock(x + 1, y + -8, z + 52, Blocks.stone, 0, 3);
		world.setBlock(x + 2, y + -8, z + 52, Blocks.stone, 0, 3);
		world.setBlock(x + 3, y + -8, z + 52, Blocks.stone, 0, 3);
		world.setBlock(x + 4, y + -8, z + 52, Blocks.stone, 0, 3);
		world.setBlock(x + 5, y + -8, z + 52, Blocks.stone, 0, 3);
		world.setBlock(x + 6, y + -8, z + 52, Blocks.stone, 0, 3);
		world.setBlock(x + 7, y + -8, z + 52, Blocks.stone, 0, 3);
		world.setBlock(x + 8, y + -8, z + 52, Blocks.stone, 0, 3);
		world.setBlock(x + 9, y + -8, z + 52, Blocks.stone, 0, 3);
		world.setBlock(x + 10, y + -8, z + 52, Blocks.stone, 0, 3);
		world.setBlock(x + 11, y + -8, z + 52, Blocks.stone, 0, 3);
		world.setBlock(x + 12, y + -8, z + 52, Blocks.stone, 0, 3);
		world.setBlock(x + 13, y + -8, z + 52, Blocks.stone, 0, 3);
		world.setBlock(x + 14, y + -8, z + 52, Blocks.stone, 0, 3);
		world.setBlock(x + 15, y + -8, z + 52, Blocks.stone, 0, 3);
		world.setBlock(x + 16, y + -8, z + 52, Blocks.stone, 0, 3);
		world.setBlock(x + 17, y + -8, z + 52, Blocks.stone, 0, 3);
		world.setBlock(x + 0, y + -8, z + 53, Blocks.bedrock, 0, 3);
		world.setBlock(x + 1, y + -8, z + 53, Blocks.stone, 0, 3);
		world.setBlock(x + 9, y + -8, z + 53, Blocks.stone, 0, 3);
		world.setBlock(x + 17, y + -8, z + 53, Blocks.stone, 0, 3);
		world.setBlock(x + 0, y + -8, z + 54, Blocks.bedrock, 0, 3);
		world.setBlock(x + 1, y + -8, z + 54, Blocks.stone, 0, 3);
		world.setBlock(x + 9, y + -8, z + 54, Blocks.stone, 0, 3);
		world.setBlock(x + 17, y + -8, z + 54, Blocks.stone, 0, 3);
		world.setBlock(x + 0, y + -8, z + 55, Blocks.bedrock, 0, 3);
		world.setBlock(x + 1, y + -8, z + 55, Blocks.stone, 0, 3);
		world.setBlock(x + 9, y + -8, z + 55, Blocks.stone, 0, 3);
		world.setBlock(x + 17, y + -8, z + 55, Blocks.stone, 0, 3);
		world.setBlock(x + 0, y + -8, z + 56, Blocks.bedrock, 0, 3);
		world.setBlock(x + 1, y + -8, z + 56, Blocks.stone, 0, 3);
		world.setBlock(x + 9, y + -8, z + 56, Blocks.stone, 0, 3);
		world.setBlock(x + 13, y + -8, z + 56, Blocks.cobblestone, 0, 3);
		world.setBlock(x + 14, y + -8, z + 56, Blocks.stone_stairs, 2, 3);
		world.setBlock(x + 17, y + -8, z + 56, Blocks.stone, 0, 3);
		world.setBlock(x + 0, y + -8, z + 57, Blocks.bedrock, 0, 3);
		world.setBlock(x + 1, y + -8, z + 57, Blocks.stone, 0, 3);
		world.setBlock(x + 9, y + -8, z + 57, Blocks.stone, 0, 3);
		world.setBlock(x + 14, y + -8, z + 57, Blocks.stone_slab, 11, 3);
		world.setBlock(x + 17, y + -8, z + 57, Blocks.stone, 0, 3);
		world.setBlock(x + 0, y + -8, z + 58, Blocks.bedrock, 0, 3);
		world.setBlock(x + 1, y + -8, z + 58, Blocks.stone, 0, 3);
		world.setBlock(x + 9, y + -8, z + 58, Blocks.stone, 0, 3);
		world.setBlock(x + 17, y + -8, z + 58, Blocks.stone, 0, 3);
		world.setBlock(x + 0, y + -8, z + 59, Blocks.bedrock, 0, 3);
		world.setBlock(x + 1, y + -8, z + 59, Blocks.stone, 0, 3);
		world.setBlock(x + 9, y + -8, z + 59, Blocks.stone, 0, 3);
		world.setBlock(x + 17, y + -8, z + 59, Blocks.stone, 0, 3);
		world.setBlock(x + 0, y + -8, z + 60, Blocks.bedrock, 0, 3);
		world.setBlock(x + 1, y + -8, z + 60, Blocks.stone, 0, 3);
		world.setBlock(x + 2, y + -8, z + 60, Blocks.stone, 0, 3);
		world.setBlock(x + 3, y + -8, z + 60, Blocks.stone, 0, 3);
		world.setBlock(x + 4, y + -8, z + 60, Blocks.stone, 0, 3);
		world.setBlock(x + 5, y + -8, z + 60, Blocks.stone, 0, 3);
		world.setBlock(x + 6, y + -8, z + 60, Blocks.stone, 0, 3);
		world.setBlock(x + 7, y + -8, z + 60, Blocks.stone, 0, 3);
		world.setBlock(x + 8, y + -8, z + 60, Blocks.stone, 0, 3);
		world.setBlock(x + 9, y + -8, z + 60, Blocks.stone, 0, 3);
		world.setBlock(x + 10, y + -8, z + 60, Blocks.stone, 0, 3);
		world.setBlock(x + 11, y + -8, z + 60, Blocks.stone, 0, 3);
		world.setBlock(x + 12, y + -8, z + 60, Blocks.stone, 0, 3);
		world.setBlock(x + 13, y + -8, z + 60, Blocks.stone, 0, 3);
		world.setBlock(x + 14, y + -8, z + 60, Blocks.stone, 0, 3);
		world.setBlock(x + 15, y + -8, z + 60, Blocks.stone, 0, 3);
		world.setBlock(x + 16, y + -8, z + 60, Blocks.stone, 0, 3);
		world.setBlock(x + 17, y + -8, z + 60, Blocks.stone, 0, 3);
		world.setBlock(x + 0, y + -8, z + 61, Blocks.bedrock, 0, 3);
		world.setBlock(x + 1, y + -8, z + 61, Blocks.bedrock, 0, 3);
		world.setBlock(x + 2, y + -8, z + 61, Blocks.bedrock, 0, 3);
		world.setBlock(x + 3, y + -8, z + 61, Blocks.bedrock, 0, 3);
		world.setBlock(x + 4, y + -8, z + 61, Blocks.bedrock, 0, 3);
		world.setBlock(x + 5, y + -8, z + 61, Blocks.bedrock, 0, 3);
		world.setBlock(x + 6, y + -8, z + 61, Blocks.bedrock, 0, 3);
		world.setBlock(x + 7, y + -8, z + 61, Blocks.bedrock, 0, 3);
		world.setBlock(x + 8, y + -8, z + 61, Blocks.bedrock, 0, 3);
		world.setBlock(x + 9, y + -8, z + 61, Blocks.bedrock, 0, 3);
		world.setBlock(x + 0, y + -7, z + 3, Blocks.bedrock, 0, 3);
		world.setBlock(x + 1, y + -7, z + 3, Blocks.bedrock, 0, 3);
		world.setBlock(x + 2, y + -7, z + 3, Blocks.bedrock, 0, 3);
		world.setBlock(x + 3, y + -7, z + 3, Blocks.bedrock, 0, 3);
		world.setBlock(x + 4, y + -7, z + 3, Blocks.bedrock, 0, 3);
		world.setBlock(x + 5, y + -7, z + 3, Blocks.bedrock, 0, 3);
		world.setBlock(x + 6, y + -7, z + 3, Blocks.bedrock, 0, 3);
		world.setBlock(x + 7, y + -7, z + 3, Blocks.bedrock, 0, 3);
		world.setBlock(x + 8, y + -7, z + 3, Blocks.bedrock, 0, 3);
		world.setBlock(x + 9, y + -7, z + 3, Blocks.bedrock, 0, 3);
		world.setBlock(x + 10, y + -7, z + 3, Blocks.bedrock, 0, 3);
		world.setBlock(x + 11, y + -7, z + 3, Blocks.bedrock, 0, 3);
		world.setBlock(x + 12, y + -7, z + 3, Blocks.bedrock, 0, 3);
		world.setBlock(x + 13, y + -7, z + 3, Blocks.bedrock, 0, 3);
		world.setBlock(x + 14, y + -7, z + 3, Blocks.bedrock, 0, 3);
		world.setBlock(x + 15, y + -7, z + 3, Blocks.bedrock, 0, 3);
		world.setBlock(x + 16, y + -7, z + 3, Blocks.bedrock, 0, 3);
		world.setBlock(x + 17, y + -7, z + 3, Blocks.bedrock, 0, 3);
		world.setBlock(x + 18, y + -7, z + 3, Blocks.bedrock, 0, 3);
		world.setBlock(x + 19, y + -7, z + 3, Blocks.bedrock, 0, 3);
		world.setBlock(x + 20, y + -7, z + 3, Blocks.bedrock, 0, 3);
		world.setBlock(x + 21, y + -7, z + 3, Blocks.bedrock, 0, 3);
		world.setBlock(x + 22, y + -7, z + 3, Blocks.bedrock, 0, 3);
		world.setBlock(x + 23, y + -7, z + 3, Blocks.bedrock, 0, 3);
		world.setBlock(x + 24, y + -7, z + 3, Blocks.bedrock, 0, 3);
		world.setBlock(x + 25, y + -7, z + 3, Blocks.bedrock, 0, 3);
		world.setBlock(x + 26, y + -7, z + 3, Blocks.bedrock, 0, 3);
		world.setBlock(x + 27, y + -7, z + 3, Blocks.bedrock, 0, 3);
		world.setBlock(x + 28, y + -7, z + 3, Blocks.bedrock, 0, 3);
		world.setBlock(x + 0, y + -7, z + 4, Blocks.bedrock, 0, 3);
		world.setBlock(x + 1, y + -7, z + 4, Blocks.stone, 0, 3);
		world.setBlock(x + 2, y + -7, z + 4, Blocks.stone, 0, 3);
		world.setBlock(x + 3, y + -7, z + 4, Blocks.stone, 0, 3);
		world.setBlock(x + 4, y + -7, z + 4, Blocks.stone, 0, 3);
		world.setBlock(x + 5, y + -7, z + 4, Blocks.stone, 0, 3);
		world.setBlock(x + 6, y + -7, z + 4, Blocks.stone, 0, 3);
		world.setBlock(x + 7, y + -7, z + 4, Blocks.stone, 0, 3);
		world.setBlock(x + 8, y + -7, z + 4, Blocks.stone, 0, 3);
		world.setBlock(x + 9, y + -7, z + 4, Blocks.stone, 0, 3);
		world.setBlock(x + 10, y + -7, z + 4, Blocks.planks, 0, 3);
		world.setBlock(x + 11, y + -7, z + 4, Blocks.planks, 0, 3);
		world.setBlock(x + 12, y + -7, z + 4, Blocks.planks, 0, 3);
		world.setBlock(x + 13, y + -7, z + 4, Blocks.planks, 0, 3);
		world.setBlock(x + 14, y + -7, z + 4, Blocks.planks, 0, 3);
		world.setBlock(x + 15, y + -7, z + 4, Blocks.planks, 0, 3);
		world.setBlock(x + 16, y + -7, z + 4, Blocks.planks, 0, 3);
		world.setBlock(x + 17, y + -7, z + 4, Blocks.planks, 0, 3);
		world.setBlock(x + 18, y + -7, z + 4, Blocks.planks, 0, 3);
		world.setBlock(x + 19, y + -7, z + 4, Blocks.planks, 0, 3);
		world.setBlock(x + 20, y + -7, z + 4, Blocks.planks, 0, 3);
		world.setBlock(x + 21, y + -7, z + 4, Blocks.planks, 0, 3);
		world.setBlock(x + 22, y + -7, z + 4, Blocks.planks, 0, 3);
		world.setBlock(x + 23, y + -7, z + 4, Blocks.planks, 0, 3);
		world.setBlock(x + 24, y + -7, z + 4, Blocks.planks, 0, 3);
		world.setBlock(x + 25, y + -7, z + 4, Blocks.planks, 0, 3);
		world.setBlock(x + 26, y + -7, z + 4, Blocks.planks, 0, 3);
		world.setBlock(x + 27, y + -7, z + 4, Blocks.planks, 0, 3);
		world.setBlock(x + 28, y + -7, z + 4, Blocks.bedrock, 0, 3);
		world.setBlock(x + 0, y + -7, z + 5, Blocks.bedrock, 0, 3);
		world.setBlock(x + 1, y + -7, z + 5, Blocks.stone, 0, 3);
		world.setBlock(x + 9, y + -7, z + 5, Blocks.stone, 0, 3);
		world.setBlock(x + 10, y + -7, z + 5, Blocks.planks, 0, 3);
		world.setBlock(x + 27, y + -7, z + 5, Blocks.planks, 0, 3);
		world.setBlock(x + 28, y + -7, z + 5, Blocks.bedrock, 0, 3);
		world.setBlock(x + 0, y + -7, z + 6, Blocks.bedrock, 0, 3);
		world.setBlock(x + 1, y + -7, z + 6, Blocks.stone, 0, 3);
		world.setBlock(x + 9, y + -7, z + 6, Blocks.stone, 0, 3);
		world.setBlock(x + 10, y + -7, z + 6, Blocks.planks, 0, 3);
		world.setBlock(x + 27, y + -7, z + 6, Blocks.planks, 0, 3);
		world.setBlock(x + 28, y + -7, z + 6, Blocks.bedrock, 0, 3);
		world.setBlock(x + 0, y + -7, z + 7, Blocks.bedrock, 0, 3);
		world.setBlock(x + 1, y + -7, z + 7, Blocks.stone, 0, 3);
		world.setBlock(x + 9, y + -7, z + 7, Blocks.stone, 0, 3);
		world.setBlock(x + 10, y + -7, z + 7, Blocks.planks, 0, 3);
		world.setBlock(x + 27, y + -7, z + 7, Blocks.planks, 0, 3);
		world.setBlock(x + 28, y + -7, z + 7, Blocks.bedrock, 0, 3);
		world.setBlock(x + 0, y + -7, z + 8, Blocks.bedrock, 0, 3);
		world.setBlock(x + 1, y + -7, z + 8, Blocks.stone, 0, 3);
		world.setBlock(x + 5, y + -7, z + 8, Blocks.mob_spawner, 0, 3);
		world.setBlock(x + 9, y + -7, z + 8, Blocks.stone, 0, 3);
		world.setBlock(x + 10, y + -7, z + 8, Blocks.planks, 0, 3);
		world.setBlock(x + 27, y + -7, z + 8, Blocks.planks, 0, 3);
		world.setBlock(x + 28, y + -7, z + 8, Blocks.bedrock, 0, 3);
		world.setBlock(x + 0, y + -7, z + 9, Blocks.bedrock, 0, 3);
		world.setBlock(x + 1, y + -7, z + 9, Blocks.stone, 0, 3);
		world.setBlock(x + 9, y + -7, z + 9, Blocks.stone, 0, 3);
		world.setBlock(x + 10, y + -7, z + 9, Blocks.planks, 0, 3);
		world.setBlock(x + 27, y + -7, z + 9, Blocks.planks, 0, 3);
		world.setBlock(x + 28, y + -7, z + 9, Blocks.bedrock, 0, 3);
		world.setBlock(x + 0, y + -7, z + 10, Blocks.bedrock, 0, 3);
		world.setBlock(x + 1, y + -7, z + 10, Blocks.stone, 0, 3);
		world.setBlock(x + 9, y + -7, z + 10, Blocks.stone, 0, 3);
		world.setBlock(x + 10, y + -7, z + 10, Blocks.planks, 0, 3);
		world.setBlock(x + 27, y + -7, z + 10, Blocks.planks, 0, 3);
		world.setBlock(x + 28, y + -7, z + 10, Blocks.bedrock, 0, 3);
		world.setBlock(x + 0, y + -7, z + 11, Blocks.bedrock, 0, 3);
		world.setBlock(x + 1, y + -7, z + 11, Blocks.stone, 0, 3);
		world.setBlock(x + 9, y + -7, z + 11, Blocks.stone, 0, 3);
		world.setBlock(x + 10, y + -7, z + 11, Blocks.planks, 0, 3);
		world.setBlock(x + 27, y + -7, z + 11, Blocks.planks, 0, 3);
		world.setBlock(x + 28, y + -7, z + 11, Blocks.bedrock, 0, 3);
		world.setBlock(x + 0, y + -7, z + 12, Blocks.bedrock, 0, 3);
		world.setBlock(x + 1, y + -7, z + 12, Blocks.stone, 0, 3);
		world.setBlock(x + 2, y + -7, z + 12, Blocks.stone, 0, 3);
		world.setBlock(x + 3, y + -7, z + 12, Blocks.stone, 0, 3);
		world.setBlock(x + 4, y + -7, z + 12, Blocks.stone, 0, 3);
		world.setBlock(x + 5, y + -7, z + 12, Blocks.stone, 0, 3);
		world.setBlock(x + 6, y + -7, z + 12, Blocks.stone, 0, 3);
		world.setBlock(x + 7, y + -7, z + 12, Blocks.stone, 0, 3);
		world.setBlock(x + 8, y + -7, z + 12, Blocks.stone, 0, 3);
		world.setBlock(x + 9, y + -7, z + 12, Blocks.stone, 0, 3);
		world.setBlock(x + 10, y + -7, z + 12, Blocks.planks, 0, 3);
		world.setBlock(x + 27, y + -7, z + 12, Blocks.planks, 0, 3);
		world.setBlock(x + 28, y + -7, z + 12, Blocks.bedrock, 0, 3);
		world.setBlock(x + 0, y + -7, z + 13, Blocks.bedrock, 0, 3);
		world.setBlock(x + 1, y + -7, z + 13, Blocks.stone, 0, 3);
		world.setBlock(x + 9, y + -7, z + 13, Blocks.stone, 0, 3);
		world.setBlock(x + 10, y + -7, z + 13, Blocks.planks, 0, 3);
		world.setBlock(x + 27, y + -7, z + 13, Blocks.planks, 0, 3);
		world.setBlock(x + 28, y + -7, z + 13, Blocks.bedrock, 0, 3);
		world.setBlock(x + 0, y + -7, z + 14, Blocks.bedrock, 0, 3);
		world.setBlock(x + 1, y + -7, z + 14, Blocks.stone, 0, 3);
		world.setBlock(x + 9, y + -7, z + 14, Blocks.stone, 0, 3);
		world.setBlock(x + 10, y + -7, z + 14, Blocks.planks, 0, 3);
		world.setBlock(x + 27, y + -7, z + 14, Blocks.planks, 0, 3);
		world.setBlock(x + 28, y + -7, z + 14, Blocks.bedrock, 0, 3);
		world.setBlock(x + 0, y + -7, z + 15, Blocks.bedrock, 0, 3);
		world.setBlock(x + 1, y + -7, z + 15, Blocks.stone, 0, 3);
		world.setBlock(x + 9, y + -7, z + 15, Blocks.stone, 0, 3);
		world.setBlock(x + 10, y + -7, z + 15, Blocks.planks, 0, 3);
		world.setBlock(x + 27, y + -7, z + 15, Blocks.planks, 0, 3);
		world.setBlock(x + 28, y + -7, z + 15, Blocks.bedrock, 0, 3);
		world.setBlock(x + 0, y + -7, z + 16, Blocks.bedrock, 0, 3);
		world.setBlock(x + 1, y + -7, z + 16, Blocks.stone, 0, 3);
		world.setBlock(x + 5, y + -7, z + 16, Blocks.mob_spawner, 0, 3);
		world.setBlock(x + 9, y + -7, z + 16, Blocks.stone, 0, 3);
		world.setBlock(x + 10, y + -7, z + 16, Blocks.planks, 0, 3);
		world.setBlock(x + 27, y + -7, z + 16, Blocks.planks, 0, 3);
		world.setBlock(x + 28, y + -7, z + 16, Blocks.bedrock, 0, 3);
		world.setBlock(x + 0, y + -7, z + 17, Blocks.bedrock, 0, 3);
		world.setBlock(x + 1, y + -7, z + 17, Blocks.stone, 0, 3);
		world.setBlock(x + 9, y + -7, z + 17, Blocks.stone, 0, 3);
		world.setBlock(x + 10, y + -7, z + 17, Blocks.planks, 0, 3);
		world.setBlock(x + 11, y + -7, z + 17, Blocks.planks, 0, 3);
		world.setBlock(x + 12, y + -7, z + 17, Blocks.planks, 0, 3);
		world.setBlock(x + 13, y + -7, z + 17, Blocks.planks, 0, 3);
		world.setBlock(x + 14, y + -7, z + 17, Blocks.planks, 0, 3);
		world.setBlock(x + 15, y + -7, z + 17, Blocks.planks, 0, 3);
		world.setBlock(x + 16, y + -7, z + 17, Blocks.planks, 0, 3);
		world.setBlock(x + 17, y + -7, z + 17, Blocks.planks, 0, 3);
		world.setBlock(x + 18, y + -7, z + 17, Blocks.planks, 0, 3);
		world.setBlock(x + 19, y + -7, z + 17, Blocks.planks, 0, 3);
		world.setBlock(x + 20, y + -7, z + 17, Blocks.planks, 0, 3);
		world.setBlock(x + 21, y + -7, z + 17, Blocks.planks, 0, 3);
		world.setBlock(x + 22, y + -7, z + 17, Blocks.planks, 0, 3);
		world.setBlock(x + 23, y + -7, z + 17, Blocks.planks, 0, 3);
		world.setBlock(x + 24, y + -7, z + 17, Blocks.planks, 0, 3);
		world.setBlock(x + 25, y + -7, z + 17, Blocks.planks, 0, 3);
		world.setBlock(x + 26, y + -7, z + 17, Blocks.planks, 0, 3);
		world.setBlock(x + 27, y + -7, z + 17, Blocks.planks, 0, 3);
		world.setBlock(x + 28, y + -7, z + 17, Blocks.bedrock, 0, 3);
		world.setBlock(x + 0, y + -7, z + 18, Blocks.bedrock, 0, 3);
		world.setBlock(x + 1, y + -7, z + 18, Blocks.stone, 0, 3);
		world.setBlock(x + 9, y + -7, z + 18, Blocks.stone, 0, 3);
		world.setBlock(x + 10, y + -7, z + 18, Blocks.bedrock, 0, 3);
		world.setBlock(x + 11, y + -7, z + 18, Blocks.bedrock, 0, 3);
		world.setBlock(x + 12, y + -7, z + 18, Blocks.bedrock, 0, 3);
		world.setBlock(x + 13, y + -7, z + 18, Blocks.bedrock, 0, 3);
		world.setBlock(x + 14, y + -7, z + 18, Blocks.bedrock, 0, 3);
		world.setBlock(x + 15, y + -7, z + 18, Blocks.bedrock, 0, 3);
		world.setBlock(x + 16, y + -7, z + 18, Blocks.bedrock, 0, 3);
		world.setBlock(x + 17, y + -7, z + 18, Blocks.bedrock, 0, 3);
		world.setBlock(x + 18, y + -7, z + 18, Blocks.bedrock, 0, 3);
		world.setBlock(x + 19, y + -7, z + 18, Blocks.bedrock, 0, 3);
		world.setBlock(x + 20, y + -7, z + 18, Blocks.bedrock, 0, 3);
		world.setBlock(x + 21, y + -7, z + 18, Blocks.bedrock, 0, 3);
		world.setBlock(x + 22, y + -7, z + 18, Blocks.bedrock, 0, 3);
		world.setBlock(x + 23, y + -7, z + 18, Blocks.bedrock, 0, 3);
		world.setBlock(x + 24, y + -7, z + 18, Blocks.bedrock, 0, 3);
		world.setBlock(x + 25, y + -7, z + 18, Blocks.bedrock, 0, 3);
		world.setBlock(x + 26, y + -7, z + 18, Blocks.bedrock, 0, 3);
		world.setBlock(x + 27, y + -7, z + 18, Blocks.bedrock, 0, 3);
		world.setBlock(x + 28, y + -7, z + 18, Blocks.bedrock, 0, 3);
		world.setBlock(x + 0, y + -7, z + 19, Blocks.bedrock, 0, 3);
		world.setBlock(x + 1, y + -7, z + 19, Blocks.stone, 0, 3);
		world.setBlock(x + 9, y + -7, z + 19, Blocks.stone, 0, 3);
		world.setBlock(x + 10, y + -7, z + 19, Blocks.bedrock, 0, 3);
		world.setBlock(x + 0, y + -7, z + 20, Blocks.bedrock, 0, 3);
		world.setBlock(x + 1, y + -7, z + 20, Blocks.stone, 0, 3);
		world.setBlock(x + 2, y + -7, z + 20, Blocks.stone, 0, 3);
		world.setBlock(x + 3, y + -7, z + 20, Blocks.stone, 0, 3);
		world.setBlock(x + 4, y + -7, z + 20, Blocks.stone, 0, 3);
		world.setBlock(x + 5, y + -7, z + 20, Blocks.stone, 0, 3);
		world.setBlock(x + 6, y + -7, z + 20, Blocks.stone, 0, 3);
		world.setBlock(x + 7, y + -7, z + 20, Blocks.stone, 0, 3);
		world.setBlock(x + 8, y + -7, z + 20, Blocks.stone, 0, 3);
		world.setBlock(x + 9, y + -7, z + 20, Blocks.stone, 0, 3);
		world.setBlock(x + 10, y + -7, z + 20, Blocks.bedrock, 0, 3);
		world.setBlock(x + 0, y + -7, z + 21, Blocks.bedrock, 0, 3);
		world.setBlock(x + 1, y + -7, z + 21, Blocks.stone, 0, 3);

		generate_r02(world, rand, x, y, z);
		return true;

	}
	public boolean generate_r02(World world, Random rand, int x, int y, int z)
	{

		world.setBlock(x + 9, y + -7, z + 21, Blocks.stone, 0, 3);
		world.setBlock(x + 10, y + -7, z + 21, Blocks.bedrock, 0, 3);
		world.setBlock(x + 0, y + -7, z + 22, Blocks.bedrock, 0, 3);
		world.setBlock(x + 1, y + -7, z + 22, Blocks.stone, 0, 3);
		world.setBlock(x + 9, y + -7, z + 22, Blocks.stone, 0, 3);
		world.setBlock(x + 10, y + -7, z + 22, Blocks.bedrock, 0, 3);
		world.setBlock(x + 0, y + -7, z + 23, Blocks.bedrock, 0, 3);
		world.setBlock(x + 1, y + -7, z + 23, Blocks.stone, 0, 3);
		world.setBlock(x + 9, y + -7, z + 23, Blocks.stone, 0, 3);
		world.setBlock(x + 10, y + -7, z + 23, Blocks.bedrock, 0, 3);
		world.setBlock(x + 0, y + -7, z + 24, Blocks.bedrock, 0, 3);
		world.setBlock(x + 1, y + -7, z + 24, Blocks.stone, 0, 3);
		world.setBlock(x + 5, y + -7, z + 24, Blocks.mob_spawner, 0, 3);
		world.setBlock(x + 9, y + -7, z + 24, Blocks.stone, 0, 3);
		world.setBlock(x + 10, y + -7, z + 24, Blocks.bedrock, 0, 3);
		world.setBlock(x + 0, y + -7, z + 25, Blocks.bedrock, 0, 3);
		world.setBlock(x + 1, y + -7, z + 25, Blocks.stone, 0, 3);
		world.setBlock(x + 9, y + -7, z + 25, Blocks.stone, 0, 3);
		world.setBlock(x + 10, y + -7, z + 25, Blocks.bedrock, 0, 3);
		world.setBlock(x + 0, y + -7, z + 26, Blocks.bedrock, 0, 3);
		world.setBlock(x + 1, y + -7, z + 26, Blocks.stone, 0, 3);
		world.setBlock(x + 9, y + -7, z + 26, Blocks.stone, 0, 3);
		world.setBlock(x + 10, y + -7, z + 26, Blocks.bedrock, 0, 3);
		world.setBlock(x + 0, y + -7, z + 27, Blocks.bedrock, 0, 3);
		world.setBlock(x + 1, y + -7, z + 27, Blocks.stone, 0, 3);
		world.setBlock(x + 9, y + -7, z + 27, Blocks.stone, 0, 3);
		world.setBlock(x + 10, y + -7, z + 27, Blocks.bedrock, 0, 3);
		world.setBlock(x + 0, y + -7, z + 28, Blocks.bedrock, 0, 3);
		world.setBlock(x + 1, y + -7, z + 28, Blocks.stone, 0, 3);
		world.setBlock(x + 2, y + -7, z + 28, Blocks.stone, 0, 3);
		world.setBlock(x + 3, y + -7, z + 28, Blocks.stone, 0, 3);
		world.setBlock(x + 4, y + -7, z + 28, Blocks.stone, 0, 3);
		world.setBlock(x + 5, y + -7, z + 28, Blocks.stone, 0, 3);
		world.setBlock(x + 6, y + -7, z + 28, Blocks.stone, 0, 3);
		world.setBlock(x + 7, y + -7, z + 28, Blocks.stone, 0, 3);
		world.setBlock(x + 8, y + -7, z + 28, Blocks.stone, 0, 3);
		world.setBlock(x + 9, y + -7, z + 28, Blocks.stone, 0, 3);
		world.setBlock(x + 10, y + -7, z + 28, Blocks.bedrock, 0, 3);
		world.setBlock(x + 0, y + -7, z + 29, Blocks.bedrock, 0, 3);
		world.setBlock(x + 1, y + -7, z + 29, Blocks.stone, 0, 3);
		world.setBlock(x + 9, y + -7, z + 29, Blocks.stone, 0, 3);
		world.setBlock(x + 10, y + -7, z + 29, Blocks.bedrock, 0, 3);
		world.setBlock(x + 0, y + -7, z + 30, Blocks.bedrock, 0, 3);
		world.setBlock(x + 1, y + -7, z + 30, Blocks.stone, 0, 3);
		world.setBlock(x + 9, y + -7, z + 30, Blocks.stone, 0, 3);
		world.setBlock(x + 10, y + -7, z + 30, Blocks.bedrock, 0, 3);
		world.setBlock(x + 0, y + -7, z + 31, Blocks.bedrock, 0, 3);
		world.setBlock(x + 1, y + -7, z + 31, Blocks.stone, 0, 3);
		world.setBlock(x + 9, y + -7, z + 31, Blocks.stone, 0, 3);
		world.setBlock(x + 10, y + -7, z + 31, Blocks.bedrock, 0, 3);
		world.setBlock(x + 0, y + -7, z + 32, Blocks.bedrock, 0, 3);
		world.setBlock(x + 1, y + -7, z + 32, Blocks.stone, 0, 3);
		world.setBlock(x + 5, y + -7, z + 32, Blocks.mob_spawner, 0, 3);
		world.setBlock(x + 9, y + -7, z + 32, Blocks.stone, 0, 3);
		world.setBlock(x + 10, y + -7, z + 32, Blocks.bedrock, 0, 3);
		world.setBlock(x + 0, y + -7, z + 33, Blocks.bedrock, 0, 3);
		world.setBlock(x + 1, y + -7, z + 33, Blocks.stone, 0, 3);
		world.setBlock(x + 9, y + -7, z + 33, Blocks.stone, 0, 3);
		world.setBlock(x + 10, y + -7, z + 33, Blocks.bedrock, 0, 3);
		world.setBlock(x + 0, y + -7, z + 34, Blocks.bedrock, 0, 3);
		world.setBlock(x + 1, y + -7, z + 34, Blocks.stone, 0, 3);
		world.setBlock(x + 9, y + -7, z + 34, Blocks.stone, 0, 3);
		world.setBlock(x + 10, y + -7, z + 34, Blocks.bedrock, 0, 3);
		world.setBlock(x + 0, y + -7, z + 35, Blocks.bedrock, 0, 3);
		world.setBlock(x + 1, y + -7, z + 35, Blocks.stone, 0, 3);
		world.setBlock(x + 9, y + -7, z + 35, Blocks.stone, 0, 3);
		world.setBlock(x + 10, y + -7, z + 35, Blocks.bedrock, 0, 3);
		world.setBlock(x + 0, y + -7, z + 36, Blocks.bedrock, 0, 3);
		world.setBlock(x + 1, y + -7, z + 36, Blocks.stone, 0, 3);
		world.setBlock(x + 2, y + -7, z + 36, Blocks.stone, 0, 3);
		world.setBlock(x + 3, y + -7, z + 36, Blocks.stone, 0, 3);
		world.setBlock(x + 4, y + -7, z + 36, Blocks.stone, 0, 3);
		world.setBlock(x + 5, y + -7, z + 36, Blocks.stone, 0, 3);
		world.setBlock(x + 6, y + -7, z + 36, Blocks.stone, 0, 3);
		world.setBlock(x + 7, y + -7, z + 36, Blocks.stone, 0, 3);
		world.setBlock(x + 8, y + -7, z + 36, Blocks.stone, 0, 3);
		world.setBlock(x + 9, y + -7, z + 36, Blocks.stone, 0, 3);
		world.setBlock(x + 10, y + -7, z + 36, Blocks.bedrock, 0, 3);
